Workbook

Sheet Sheet1
A1: No. | B1: 氏 名 | C1: ふ り が な | D1: カタカナ | E1: 年齢 | F1: 昭 | G1: 平 | H1: 令 | I1: 生号1 | J1: 生号2 | K1: 生年 | L1: 生月 | M1: 生日 | N1: 生年月日 | O1: 携 帯 電 話 | P1: 携1 | Q1: 携 | R1: 携2 | S1: 携3 | T1: 固 定 電 話 | U1: 固1 | V1: 固 | W1: 固2 | X1: 固3 | Y1: 郵便番号 | Z1: 郵便 | AA1: 郵- | AB1: 番号 | AC1: 住 所 | AD1: 銃所持許可証番号 | AE1: 銃交付 年号2 | AF1: 銃交付 年号1 | AG1: 銃交付 年号 | AH1: 銃交付 年 | AI1: 銃交付 月 | AJ1: 銃交付 日 | AK1: 交付年月日 | AL1: 銃免状1 | AM1: 銃免状 | AN1: 一種登録 | AO1: 銃 狩猟免状番号 | AP1: 銃 狩 | AQ1: 銃猟免状番 | AR1: 号a | AS1: 銃号2 | AT1: 銃号1 | AU1: 銃号 | AV1: 銃年 | AW1: 銃月 | AX1: 銃日 | AY1: 銃年月日 | AZ1: わな免状1 | BA1: わな免状 | BB1: わな登録 | BC1: わな 狩猟免状番号 | BD1: わな 狩 | BE1: 罠猟免状番 | BF1: 号b | BG1: 罠号2 | BH1: 罠号1 | BI1: 罠号 | BJ1: 罠年 | BK1: 罠月 | BL1: 罠日 | BM1: わな年月日 | BN1: 網免状1 | BO1: 網免状 | BP1: 網登録 | BQ1: 網 狩猟免状番号 | BR1: 網 狩 | BS1: 網猟免状番 | BT1: 号c | BU1: 網号2 | BV1: 網号1 | BW1: 網号 | BX1: 網年 | BY1: 網月 | BZ1: 網日 | CA1: 網年月日 | CB1: 狩猟免許 | CC1: 次回更新 | CD1: 男 | CE1: 女 | CF1: 捕獲員である | CG1: 捕獲員でない | CH1: 西暦 | CI1: 和暦 | CJ1: 当号 | CK1: 当年 | CL1: 当月 | CM1: 当日 | CN1: 職業 | CO1: TODAY
A2: =IF(B2="","",ROW()-ROW(会員表[#Headers])) -> 1 | B2: 見本 太郎 | C2: {=_xlfn.LET(_xlpm.s,PHONETIC(B2),_xlpm.c,_xlfn.UNICODE(MID(_xlpm.s,_xlfn.SEQUENCE(LEN(_xlpm.s)),1)),IF(_xlpm.s="","",_xlfn.CONCAT(_xlfn.UNICHAR(_xlpm.c-96*(_xlpm.c>=12449)*(_xlpm.c<=12534)))))} -> みほん たろう | D2: {=_xlfn.LET(_xlpm.s,PHONETIC(B2),_xlpm.c,_xlfn.UNICODE(MID(_xlpm.s,_xlfn.SEQUENCE(LEN(_xlpm.s)),1)),IF(_xlpm.s="","",_xlfn.CONCAT(_xlfn.UNICHAR(_xlpm.c+96*(_xlpm.c>=12353)*(_xlpm.c<=12438)))))} -> ミホン タロウ | E2: =IF(N2="","",DATEDIF(N2,TODAY(),"Y")) -> 61 | F2: =IF(I2="昭","〇","") -> 〇 | G2: =IF(I2="平","〇","") | H2: =IF(I2="令","〇","") | I2: =IF($N2="","",TEXT($N2,"gg")) -> 昭 | J2: =IF($N2="","",TEXT($N2,"ggg")) -> 昭和 | K2: =IF($N2="","",TEXT($N2,"e")) -> 40 | L2: =IF($N2="","",TEXT($N2,"m")) -> 4 | M2: =IF($N2="","",TEXT($N2,"d")) -> 1 | N2: 23833 | O2: 090-0000-0001 | P2: =IFERROR(LEFT(O2,FIND("-",O2)-1),"") -> 090 | Q2: =IFERROR(RIGHT(O2,LEN(O2)-FIND("-",O2)),"") -> 0000-0001 | R2: =IFERROR(LEFT(Q2,FIND("-",Q2)-1),"") -> 0000 | S2: =IFERROR(RIGHT(Q2,LEN(Q2)-FIND("-",Q2)),"") -> 0001 | T2: 000-000-0001 | U2: =IFERROR(LEFT(T2,FIND("-",T2)-1),"") -> 000 | V2: =IFERROR(RIGHT(T2,LEN(T2)-FIND("-",T2)),"") -> 000-0001 | W2: =IFERROR(LEFT(V2,FIND("-",V2)-1),"") -> 000 | X2: =IFERROR(RIGHT(V2,LEN(V2)-FIND("-",V2)),"") -> 0001 | Y2: 000-0001 | Z2: =IF(Y2="","",LEFT(SUBSTITUTE(ASC(Y2),"-",""),3)) -> 000 | AA2: - | AB2: =IF(Y2="","",MID(SUBSTITUTE(ASC(Y2),"-",""),4,4)) -> 0001 | AC2: 見本市見本町1丁目2-3 | AD2: 12345678901 | AE2: =IF(AK2="","",TEXT($AK2,"ggg")) -> 令和 | AF2: =IF(AK2="","",TEXT($AK2,"gg")) -> 令 | AG2: =IF(AK2="","",TEXT($AK2,"g")) -> R | AH2: =IF(AK2="","",TEXT($AK2,"e")) -> 4 | AI2: =IF(AK2="","",TEXT($AK2,"m")) -> 5 | AJ2: =IF(AK2="","",TEXT($AK2,"d")) -> 20 | AK2: 44701 | AL2: =IF(AM2="","",IF(各種設定金額!$B$7="","○○県",各種設定金額!$B$7)) -> ○○県 | AM2: ✔ | AN2: ✔ | AO2: =IF(TRIM(AQ2)="","",AP2&AQ2&AR2) -> 第 ○○ 1234561 号 | AP2: 第 ○○ | AQ2: 1234561 | AR2: 号 | AS2: =IF(AY2="","",TEXT($AY2,"ggg")) -> 令和 | AT2: =IF(AY2="","",TEXT($AY2,"gg")) -> 令 | AU2: =IF(AY2="","",TEXT($AY2,"g")) -> R | AV2: =IF(AY2="","",TEXT($AY2,"e")) -> 6 | AW2: =IF(AY2="","",TEXT($AY2,"m")) -> 6 | AX2: =IF(AY2="","",TEXT($AY2,"d")) -> 10 | AY2: 45453 | AZ2: =IF(BA2="","",IF(各種設定金額!$B$7="","○○県",各種設定金額!$B$7)) -> ○○県 | BA2: ✔ | BB2: ✔ | BC2: =IF(TRIM(BE2)="","",BD2&BE2&BF2) -> 第 ○○ 2234561 号 | BD2: 第 ○○ | BE2: 2234561 | BF2: 号 | BG2: =IF(BM2="","",TEXT($BM2,"ggg")) -> 令和 | BH2: =IF(BM2="","",TEXT($BM2,"gg")) -> 令 | BI2: =IF(BM2="","",TEXT($BM2,"g")) -> R | BJ2: =IF(BM2="","",TEXT($BM2,"e")) -> 6 | BK2: =IF(BM2="","",TEXT($BM2,"m")) -> 6 | BL2: =IF(BM2="","",TEXT($BM2,"d")) -> 10 | BM2: 45453 | BN2: =IF(BO2="","",IF(各種設定金額!$B$7="","○○県",各種設定金額!$B$7)) | BQ2: =IF(TRIM(BS2)="","",BR2&BS2&BT2) | BT2: 号 | BU2: =IF(CA2="","",TEXT($CA2,"ggg")) | BV2: =IF(CA2="","",TEXT($CA2,"gg")) | BW2: =IF(CA2="","",TEXT($CA2,"g")) | BX2: =IF(CA2="","",TEXT($CA2,"e")) | BY2: =IF(CA2="","",TEXT($CA2,"m")) | BZ2: =IF(CA2="","",TEXT($CA2,"d")) | CB2: =IF(COUNT(AY2,BM2,CA2)=0,"",TEXT(DATE(YEAR(MIN(AY2,BM2,CA2))+3,9,14),"g")) -> R | CC2: =IF(COUNT(AY2,BM2,CA2)=0,"",VALUE(TEXT(DATE(YEAR(MIN(AY2,BM2,CA2))+3,9,14),"e"))) -> 9 | CD2: 〇 | CG2: ✔ | CH2: =YEAR(TODAY()) -> 2026 | CI2: =TEXT($CO2,"ggg") -> 令和 | CJ2: =TEXT($CO2,"g") -> R | CK2: =TEXT($CO2,"e") -> 8 | CL2: =MONTH(TODAY()) -> 10 | CM2: =DAY(TODAY()) -> 24 | CN2: 会社員 | CO2: =TODAY() -> 46319
A3: =IF(B3="","",ROW()-ROW(会員表[#Headers])) -> 2 | B3: 例示 花子 | C3: {=_xlfn.LET(_xlpm.s,PHONETIC(B3),_xlpm.c,_xlfn.UNICODE(MID(_xlpm.s,_xlfn.SEQUENCE(LEN(_xlpm.s)),1)),IF(_xlpm.s="","",_xlfn.CONCAT(_xlfn.UNICHAR(_xlpm.c-96*(_xlpm.c>=12449)*(_xlpm.c<=12534)))))} -> れいじ はなこ | D3: {=_xlfn.LET(_xlpm.s,PHONETIC(B3),_xlpm.c,_xlfn.UNICODE(MID(_xlpm.s,_xlfn.SEQUENCE(LEN(_xlpm.s)),1)),IF(_xlpm.s="","",_xlfn.CONCAT(_xlfn.UNICHAR(_xlpm.c+96*(_xlpm.c>=12353)*(_xlpm.c<=12438)))))} -> レイジ ハナコ | E3: =IF(N3="","",DATEDIF(N3,TODAY(),"Y")) -> 46 | F3: =IF(I3="昭","〇","") -> 〇 | G3: =IF(I3="平","〇","") | H3: =IF(I3="令","〇","") | I3: =IF($N3="","",TEXT($N3,"gg")) -> 昭 | J3: =IF($N3="","",TEXT($N3,"ggg")) -> 昭和 | K3: =IF($N3="","",TEXT($N3,"e")) -> 55 | L3: =IF($N3="","",TEXT($N3,"m")) -> 7 | M3: =IF($N3="","",TEXT($N3,"d")) -> 15 | N3: 29417 | O3: 080-0000-0002 | P3: =IFERROR(LEFT(O3,FIND("-",O3)-1),"") -> 080 | Q3: =IFERROR(RIGHT(O3,LEN(O3)-FIND("-",O3)),"") -> 0000-0002 | R3: =IFERROR(LEFT(Q3,FIND("-",Q3)-1),"") -> 0000 | S3: =IFERROR(RIGHT(Q3,LEN(Q3)-FIND("-",Q3)),"") -> 0002 | U3: =IFERROR(LEFT(T3,FIND("-",T3)-1),"") | V3: =IFERROR(RIGHT(T3,LEN(T3)-FIND("-",T3)),"") | W3: =IFERROR(LEFT(V3,FIND("-",V3)-1),"") | X3: =IFERROR(RIGHT(V3,LEN(V3)-FIND("-",V3)),"") | Y3: 000-0002 | Z3: =IF(Y3="","",LEFT(SUBSTITUTE(ASC(Y3),"-",""),3)) -> 000 | AA3: - | AB3: =IF(Y3="","",MID(SUBSTITUTE(ASC(Y3),"-",""),4,4)) -> 0002 | AC3: 例示市例示町2丁目3-4 | AE3: =IF(AK3="","",TEXT($AK3,"ggg")) | AF3: =IF(AK3="","",TEXT($AK3,"gg")) | AG3: =IF(AK3="","",TEXT($AK3,"g")) | AH3: =IF(AK3="","",TEXT($AK3,"e")) | AI3: =IF(AK3="","",TEXT($AK3,"m")) | AJ3: =IF(AK3="","",TEXT($AK3,"d")) | AL3: =IF(AM3="","",IF(各種設定金額!$B$7="","○○県",各種設定金額!$B$7)) | AO3: =IF(TRIM(AQ3)="","",AP3&AQ3&AR3) | AR3: 号 | AS3: =IF(AY3="","",TEXT($AY3,"ggg")) | AT3: =IF(AY3="","",TEXT($AY3,"gg")) | AU3: =IF(AY3="","",TEXT($AY3,"g")) | AV3: =IF(AY3="","",TEXT($AY3,"e")) | AW3: =IF(AY3="","",TEXT($AY3,"m")) | AX3: =IF(AY3="","",TEXT($AY3,"d")) | AZ3: =IF(BA3="","",IF(各種設定金額!$B$7="","○○県",各種設定金額!$B$7)) -> ○○県 | BA3: ✔ | BB3: ✔ | BC3: =IF(TRIM(BE3)="","",BD3&BE3&BF3) -> 第 ○○ 2234562 号 | BD3: 第 ○○ | BE3: 2234562 | BF3: 号 | BG3: =IF(BM3="","",TEXT($BM3,"ggg")) -> 令和 | BH3: =IF(BM3="","",TEXT($BM3,"gg")) -> 令 | BI3: =IF(BM3="","",TEXT($BM3,"g")) -> R | BJ3: =IF(BM3="","",TEXT($BM3,"e")) -> 5 | BK3: =IF(BM3="","",TEXT($BM3,"m")) -> 8 | BL3: =IF(BM3="","",TEXT($BM3,"d")) -> 1 | BM3: 45139 | BN3: =IF(BO3="","",IF(各種設定金額!$B$7="","○○県",各種設定金額!$B$7)) | BQ3: =IF(TRIM(BS3)="","",BR3&BS3&BT3) | BT3: 号 | BU3: =IF(CA3="","",TEXT($CA3,"ggg")) | BV3: =IF(CA3="","",TEXT($CA3,"gg")) | BW3: =IF(CA3="","",TEXT($CA3,"g")) | BX3: =IF(CA3="","",TEXT($CA3,"e")) | BY3: =IF(CA3="","",TEXT($CA3,"m")) | BZ3: =IF(CA3="","",TEXT($CA3,"d")) | CB3: =IF(COUNT(AY3,BM3,CA3)=0,"",TEXT(DATE(YEAR(MIN(AY3,BM3,CA3))+3,9,14),"g")) -> R | CC3: =IF(COUNT(AY3,BM3,CA3)=0,"",VALUE(TEXT(DATE(YEAR(MIN(AY3,BM3,CA3))+3,9,14),"e"))) -> 8 | CE3: 〇 | CG3: ✔ | CH3: =YEAR(TODAY()) -> 2026 | CI3: =TEXT($CO3,"ggg") -> 令和 | CJ3: =TEXT($CO3,"g") -> R | CK3: =TEXT($CO3,"e") -> 8 | CL3: =MONTH(TODAY()) -> 10 | CM3: =DAY(TODAY()) -> 24 | CN3: 農業 | CO3: =TODAY() -> 46319
A4: =IF(B4="","",ROW()-ROW(会員表[#Headers])) -> 3 | B4: 記入 次郎 | C4: {=_xlfn.LET(_xlpm.s,PHONETIC(B4),_xlpm.c,_xlfn.UNICODE(MID(_xlpm.s,_xlfn.SEQUENCE(LEN(_xlpm.s)),1)),IF(_xlpm.s="","",_xlfn.CONCAT(_xlfn.UNICHAR(_xlpm.c-96*(_xlpm.c>=12449)*(_xlpm.c<=12534)))))} -> きにゅう じろう | D4: {=_xlfn.LET(_xlpm.s,PHONETIC(B4),_xlpm.c,_xlfn.UNICODE(MID(_xlpm.s,_xlfn.SEQUENCE(LEN(_xlpm.s)),1)),IF(_xlpm.s="","",_xlfn.CONCAT(_xlfn.UNICHAR(_xlpm.c+96*(_xlpm.c>=12353)*(_xlpm.c<=12438)))))} -> キニュウ ジロウ | E4: =IF(N4="","",DATEDIF(N4,TODAY(),"Y")) -> 67 | F4: =IF(I4="昭","〇","") -> 〇 | G4: =IF(I4="平","〇","") | H4: =IF(I4="令","〇","") | I4: =IF($N4="","",TEXT($N4,"gg")) -> 昭 | J4: =IF($N4="","",TEXT($N4,"ggg")) -> 昭和 | K4: =IF($N4="","",TEXT($N4,"e")) -> 33 | L4: =IF($N4="","",TEXT($N4,"m")) -> 11 | M4: =IF($N4="","",TEXT($N4,"d")) -> 20 | N4: 21509 | O4: 070-0000-0003 | P4: =IFERROR(LEFT(O4,FIND("-",O4)-1),"") -> 070 | Q4: =IFERROR(RIGHT(O4,LEN(O4)-FIND("-",O4)),"") -> 0000-0003 | R4: =IFERROR(LEFT(Q4,FIND("-",Q4)-1),"") -> 0000 | S4: =IFERROR(RIGHT(Q4,LEN(Q4)-FIND("-",Q4)),"") -> 0003 | U4: =IFERROR(LEFT(T4,FIND("-",T4)-1),"") | V4: =IFERROR(RIGHT(T4,LEN(T4)-FIND("-",T4)),"") | W4: =IFERROR(LEFT(V4,FIND("-",V4)-1),"") | X4: =IFERROR(RIGHT(V4,LEN(V4)-FIND("-",V4)),"") | Y4: 000-0003 | Z4: =IF(Y4="","",LEFT(SUBSTITUTE(ASC(Y4),"-",""),3)) -> 000 | AA4: - | AB4: =IF(Y4="","",MID(SUBSTITUTE(ASC(Y4),"-",""),4,4)) -> 0003 | AC4: 記入市記入町3丁目4-5 | AD4: 12345678903 | AE4: =IF(AK4="","",TEXT($AK4,"ggg")) -> 令和 | AF4: =IF(AK4="","",TEXT($AK4,"gg")) -> 令 | AG4: =IF(AK4="","",TEXT($AK4,"g")) -> R | AH4: =IF(AK4="","",TEXT($AK4,"e")) -> 3 | AI4: =IF(AK4="","",TEXT($AK4,"m")) -> 3 | AJ4: =IF(AK4="","",TEXT($AK4,"d")) -> 15 | AK4: 44270 | AL4: =IF(AM4="","",IF(各種設定金額!$B$7="","○○県",各種設定金額!$B$7)) -> ○○県 | AM4: ✔ | AN4: 2️⃣ | AO4: =IF(TRIM(AQ4)="","",AP4&AQ4&AR4) -> 第 ○○ 1234563 号 | AP4: 第 ○○ | AQ4: 1234563 | AR4: 号 | AS4: =IF(AY4="","",TEXT($AY4,"ggg")) -> 令和 | AT4: =IF(AY4="","",TEXT($AY4,"gg")) -> 令 | AU4: =IF(AY4="","",TEXT($AY4,"g")) -> R | AV4: =IF(AY4="","",TEXT($AY4,"e")) -> 7 | AW4: =IF(AY4="","",TEXT($AY4,"m")) -> 7 | AX4: =IF(AY4="","",TEXT($AY4,"d")) -> 1 | AY4: 45839 | AZ4: =IF(BA4="","",IF(各種設定金額!$B$7="","○○県",各種設定金額!$B$7)) | BC4: =IF(TRIM(BE4)="","",BD4&BE4&BF4) | BF4: 号 | BG4: =IF(BM4="","",TEXT($BM4,"ggg")) | BH4: =IF(BM4="","",TEXT($BM4,"gg")) | BI4: =IF(BM4="","",TEXT($BM4,"g")) | BJ4: =IF(BM4="","",TEXT($BM4,"e")) | BK4: =IF(BM4="","",TEXT($BM4,"m")) | BL4: =IF(BM4="","",TEXT($BM4,"d")) | BN4: =IF(BO4="","",IF(各種設定金額!$B$7="","○○県",各種設定金額!$B$7)) -> ○○県 | BO4: ✔ | BP4: ✔ | BQ4: =IF(TRIM(BS4)="","",BR4&BS4&BT4) -> 第 ○○ 3234563 号 | BR4: 第 ○○ | BS4: 3234563 | BT4: 号 | BU4: =IF(CA4="","",TEXT($CA4,"ggg")) -> 令和 | BV4: =IF(CA4="","",TEXT($CA4,"gg")) -> 令 | BW4: =IF(CA4="","",TEXT($CA4,"g")) -> R | BX4: =IF(CA4="","",TEXT($CA4,"e")) -> 7 | BY4: =IF(CA4="","",TEXT($CA4,"m")) -> 7 | BZ4: =IF(CA4="","",TEXT($CA4,"d")) -> 1 | CA4: 45839 | CB4: =IF(COUNT(AY4,BM4,CA4)=0,"",TEXT(DATE(YEAR(MIN(AY4,BM4,CA4))+3,9,14),"g")) -> R | CC4: =IF(COUNT(AY4,BM4,CA4)=0,"",VALUE(TEXT(DATE(YEAR(MIN(AY4,BM4,CA4))+3,9,14),"e"))) -> 10 | CD4: 〇 | CF4: ✔ | CH4: =YEAR(TODAY()) -> 2026 | CI4: =TEXT($CO4,"ggg") -> 令和 | CJ4: =TEXT($CO4,"g") -> R | CK4: =TEXT($CO4,"e") -> 8 | CL4: =MONTH(TODAY()) -> 10 | CM4: =DAY(TODAY()) -> 24 | CN4: 自営業 | CO4: =TODAY() -> 46319
A5: =IF(B5="","",ROW()-ROW(会員表[#Headers])) -> 4 | B5: 試験 三郎 | C5: {=_xlfn.LET(_xlpm.s,PHONETIC(B5),_xlpm.c,_xlfn.UNICODE(MID(_xlpm.s,_xlfn.SEQUENCE(LEN(_xlpm.s)),1)),IF(_xlpm.s="","",_xlfn.CONCAT(_xlfn.UNICHAR(_xlpm.c-96*(_xlpm.c>=12449)*(_xlpm.c<=12534)))))} -> しけん さぶろう | D5: {=_xlfn.LET(_xlpm.s,PHONETIC(B5),_xlpm.c,_xlfn.UNICODE(MID(_xlpm.s,_xlfn.SEQUENCE(LEN(_xlpm.s)),1)),IF(_xlpm.s="","",_xlfn.CONCAT(_xlfn.UNICHAR(_xlpm.c+96*(_xlpm.c>=12353)*(_xlpm.c<=12438)))))} -> シケン サブロウ | E5: =IF(N5="","",DATEDIF(N5,TODAY(),"Y")) -> 54 | F5: =IF(I5="昭","〇","") -> 〇 | G5: =IF(I5="平","〇","") | H5: =IF(I5="令","〇","") | I5: =IF($N5="","",TEXT($N5,"gg")) -> 昭 | J5: =IF($N5="","",TEXT($N5,"ggg")) -> 昭和 | K5: =IF($N5="","",TEXT($N5,"e")) -> 47 | L5: =IF($N5="","",TEXT($N5,"m")) -> 2 | M5: =IF($N5="","",TEXT($N5,"d")) -> 28 | N5: 26357 | O5: 090-0000-0004 | P5: =IFERROR(LEFT(O5,FIND("-",O5)-1),"") -> 090 | Q5: =IFERROR(RIGHT(O5,LEN(O5)-FIND("-",O5)),"") -> 0000-0004 | R5: =IFERROR(LEFT(Q5,FIND("-",Q5)-1),"") -> 0000 | S5: =IFERROR(RIGHT(Q5,LEN(Q5)-FIND("-",Q5)),"") -> 0004 | T5: 000-000-0004 | U5: =IFERROR(LEFT(T5,FIND("-",T5)-1),"") -> 000 | V5: =IFERROR(RIGHT(T5,LEN(T5)-FIND("-",T5)),"") -> 000-0004 | W5: =IFERROR(LEFT(V5,FIND("-",V5)-1),"") -> 000 | X5: =IFERROR(RIGHT(V5,LEN(V5)-FIND("-",V5)),"") -> 0004 | Y5: 000-0004 | Z5: =IF(Y5="","",LEFT(SUBSTITUTE(ASC(Y5),"-",""),3)) -> 000 | AA5: - | AB5: =IF(Y5="","",MID(SUBSTITUTE(ASC(Y5),"-",""),4,4)) -> 0004 | AC5: 試験市試験町4丁目5-6 | AD5: 12345678904 | AE5: =IF(AK5="","",TEXT($AK5,"ggg")) -> 令和 | AF5: =IF(AK5="","",TEXT($AK5,"gg")) -> 令 | AG5: =IF(AK5="","",TEXT($AK5,"g")) -> R | AH5: =IF(AK5="","",TEXT($AK5,"e")) -> 2 | AI5: =IF(AK5="","",TEXT($AK5,"m")) -> 9 | AJ5: =IF(AK5="","",TEXT($AK5,"d")) -> 1 | AK5: 44075 | AL5: =IF(AM5="","",IF(各種設定金額!$B$7="","○○県",各種設定金額!$B$7)) -> ○○県 | AM5: ✔ | AN5: ✔ | AO5: =IF(TRIM(AQ5)="","",AP5&AQ5&AR5) -> 第 ○○ 1234564 号 | AP5: 第 ○○ | AQ5: 1234564 | AR5: 号 | AS5: =IF(AY5="","",TEXT($AY5,"ggg")) -> 令和 | AT5: =IF(AY5="","",TEXT($AY5,"gg")) -> 令 | AU5: =IF(AY5="","",TEXT($AY5,"g")) -> R | AV5: =IF(AY5="","",TEXT($AY5,"e")) -> 5 | AW5: =IF(AY5="","",TEXT($AY5,"m")) -> 4 | AX5: =IF(AY5="","",TEXT($AY5,"d")) -> 10 | AY5: 45026 | AZ5: =IF(BA5="","",IF(各種設定金額!$B$7="","○○県",各種設定金額!$B$7)) | BC5: =IF(TRIM(BE5)="","",BD5&BE5&BF5) | BF5: 号 | BG5: =IF(BM5="","",TEXT($BM5,"ggg")) | BH5: =IF(BM5="","",TEXT($BM5,"gg")) | BI5: =IF(BM5="","",TEXT($BM5,"g")) | BJ5: =IF(BM5="","",TEXT($BM5,"e")) | BK5: =IF(BM5="","",TEXT($BM5,"m")) | BL5: =IF(BM5="","",TEXT($BM5,"d")) | BN5: =IF(BO5="","",IF(各種設定金額!$B$7="","○○県",各種設定金額!$B$7)) | BQ5: =IF(TRIM(BS5)="","",BR5&BS5&BT5) | BT5: 号 | BU5: =IF(CA5="","",TEXT($CA5,"ggg")) | BV5: =IF(CA5="","",TEXT($CA5,"gg")) | BW5: =IF(CA5="","",TEXT($CA5,"g")) | BX5: =IF(CA5="","",TEXT($CA5,"e")) | BY5: =IF(CA5="","",TEXT($CA5,"m")) | BZ5: =IF(CA5="","",TEXT($CA5,"d")) | CB5: =IF(COUNT(AY5,BM5,CA5)=0,"",TEXT(DATE(YEAR(MIN(AY5,BM5,CA5))+3,9,14),"g")) -> R | CC5: =IF(COUNT(AY5,BM5,CA5)=0,"",VALUE(TEXT(DATE(YEAR(MIN(AY5,BM5,CA5))+3,9,14),"e"))) -> 8 | CD5: 〇 | CG5: ✔ | CH5: =YEAR(TODAY()) -> 2026 | CI5: =TEXT($CO5,"ggg") -> 令和 | CJ5: =TEXT($CO5,"g") -> R | CK5: =TEXT($CO5,"e") -> 8 | CL5: =MONTH(TODAY()) -> 10 | CM5: =DAY(TODAY()) -> 24 | CN5: 公務員 | CO5: =TODAY() -> 46319
A6: =IF(B6="","",ROW()-ROW(会員表[#Headers])) -> 5 | B6: 架空 良子 | C6: {=_xlfn.LET(_xlpm.s,PHONETIC(B6),_xlpm.c,_xlfn.UNICODE(MID(_xlpm.s,_xlfn.SEQUENCE(LEN(_xlpm.s)),1)),IF(_xlpm.s="","",_xlfn.CONCAT(_xlfn.UNICHAR(_xlpm.c-96*(_xlpm.c>=12449)*(_xlpm.c<=12534)))))} -> かくう よしこ | D6: {=_xlfn.LET(_xlpm.s,PHONETIC(B6),_xlpm.c,_xlfn.UNICODE(MID(_xlpm.s,_xlfn.SEQUENCE(LEN(_xlpm.s)),1)),IF(_xlpm.s="","",_xlfn.CONCAT(_xlfn.UNICHAR(_xlpm.c+96*(_xlpm.c>=12353)*(_xlpm.c<=12438)))))} -> カクウ ヨシコ | E6: =IF(N6="","",DATEDIF(N6,TODAY(),"Y")) -> 35 | F6: =IF(I6="昭","〇","") | G6: =IF(I6="平","〇","") -> 〇 | H6: =IF(I6="令","〇","") | I6: =IF($N6="","",TEXT($N6,"gg")) -> 平 | J6: =IF($N6="","",TEXT($N6,"ggg")) -> 平成 | K6: =IF($N6="","",TEXT($N6,"e")) -> 2 | L6: =IF($N6="","",TEXT($N6,"m")) -> 12 | M6: =IF($N6="","",TEXT($N6,"d")) -> 5 | N6: 33212 | O6: 080-0000-0005 | P6: =IFERROR(LEFT(O6,FIND("-",O6)-1),"") -> 080 | Q6: =IFERROR(RIGHT(O6,LEN(O6)-FIND("-",O6)),"") -> 0000-0005 | R6: =IFERROR(LEFT(Q6,FIND("-",Q6)-1),"") -> 0000 | S6: =IFERROR(RIGHT(Q6,LEN(Q6)-FIND("-",Q6)),"") -> 0005 | U6: =IFERROR(LEFT(T6,FIND("-",T6)-1),"") | V6: =IFERROR(RIGHT(T6,LEN(T6)-FIND("-",T6)),"") | W6: =IFERROR(LEFT(V6,FIND("-",V6)-1),"") | X6: =IFERROR(RIGHT(V6,LEN(V6)-FIND("-",V6)),"") | Y6: 000-0005 | Z6: =IF(Y6="","",LEFT(SUBSTITUTE(ASC(Y6),"-",""),3)) -> 000 | AA6: - | AB6: =IF(Y6="","",MID(SUBSTITUTE(ASC(Y6),"-",""),4,4)) -> 0005 | AC6: 架空市架空町5丁目6-7 | AE6: =IF(AK6="","",TEXT($AK6,"ggg")) | AF6: =IF(AK6="","",TEXT($AK6,"gg")) | AG6: =IF(AK6="","",TEXT($AK6,"g")) | AH6: =IF(AK6="","",TEXT($AK6,"e")) | AI6: =IF(AK6="","",TEXT($AK6,"m")) | AJ6: =IF(AK6="","",TEXT($AK6,"d")) | AL6: =IF(AM6="","",IF(各種設定金額!$B$7="","○○県",各種設定金額!$B$7)) | AO6: =IF(TRIM(AQ6)="","",AP6&AQ6&AR6) | AR6: 号 | AS6: =IF(AY6="","",TEXT($AY6,"ggg")) | AT6: =IF(AY6="","",TEXT($AY6,"gg")) | AU6: =IF(AY6="","",TEXT($AY6,"g")) | AV6: =IF(AY6="","",TEXT($AY6,"e")) | AW6: =IF(AY6="","",TEXT($AY6,"m")) | AX6: =IF(AY6="","",TEXT($AY6,"d")) | AZ6: =IF(BA6="","",IF(各種設定金額!$B$7="","○○県",各種設定金額!$B$7)) -> ○○県 | BA6: ✔ | BB6: ✔ | BC6: =IF(TRIM(BE6)="","",BD6&BE6&BF6) -> 第 ○○ 2234565 号 | BD6: 第 ○○ | BE6: 2234565 | BF6: 号 | BG6: =IF(BM6="","",TEXT($BM6,"ggg")) -> 令和 | BH6: =IF(BM6="","",TEXT($BM6,"gg")) -> 令 | BI6: =IF(BM6="","",TEXT($BM6,"g")) -> R | BJ6: =IF(BM6="","",TEXT($BM6,"e")) -> 6 | BK6: =IF(BM6="","",TEXT($BM6,"m")) -> 9 | BL6: =IF(BM6="","",TEXT($BM6,"d")) -> 1 | BM6: 45536 | BN6: =IF(BO6="","",IF(各種設定金額!$B$7="","○○県",各種設定金額!$B$7)) -> ○○県 | BO6: ✔ | BP6: ✔ | BQ6: =IF(TRIM(BS6)="","",BR6&BS6&BT6) -> 第 ○○ 3234565 号 | BR6: 第 ○○ | BS6: 3234565 | BT6: 号 | BU6: =IF(CA6="","",TEXT($CA6,"ggg")) -> 令和 | BV6: =IF(CA6="","",TEXT($CA6,"gg")) -> 令 | BW6: =IF(CA6="","",TEXT($CA6,"g")) -> R | BX6: =IF(CA6="","",TEXT($CA6,"e")) -> 7 | BY6: =IF(CA6="","",TEXT($CA6,"m")) -> 10 | BZ6: =IF(CA6="","",TEXT($CA6,"d")) -> 5 | CA6: 45935 | CB6: =IF(COUNT(AY6,BM6,CA6)=0,"",TEXT(DATE(YEAR(MIN(AY6,BM6,CA6))+3,9,14),"g")) -> R | CC6: =IF(COUNT(AY6,BM6,CA6)=0,"",VALUE(TEXT(DATE(YEAR(MIN(AY6,BM6,CA6))+3,9,14),"e"))) -> 9 | CE6: 〇 | CG6: ✔ | CH6: =YEAR(TODAY()) -> 2026 | CI6: =TEXT($CO6,"ggg") -> 令和 | CJ6: =TEXT($CO6,"g") -> R | CK6: =TEXT($CO6,"e") -> 8 | CL6: =MONTH(TODAY()) -> 10 | CM6: =DAY(TODAY()) -> 24 | CN6: パート | CO6: =TODAY() -> 46319
A7: =IF(B7="","",ROW()-ROW(会員表[#Headers])) | C7: {=_xlfn.LET(_xlpm.s,PHONETIC(B7),_xlpm.c,_xlfn.UNICODE(MID(_xlpm.s,_xlfn.SEQUENCE(LEN(_xlpm.s)),1)),IF(_xlpm.s="","",_xlfn.CONCAT(_xlfn.UNICHAR(_xlpm.c-96*(_xlpm.c>=12449)*(_xlpm.c<=12534)))))} | D7: {=_xlfn.LET(_xlpm.s,PHONETIC(B7),_xlpm.c,_xlfn.UNICODE(MID(_xlpm.s,_xlfn.SEQUENCE(LEN(_xlpm.s)),1)),IF(_xlpm.s="","",_xlfn.CONCAT(_xlfn.UNICHAR(_xlpm.c+96*(_xlpm.c>=12353)*(_xlpm.c<=12438)))))} | E7: =IF(N7="","",DATEDIF(N7,TODAY(),"Y")) | F7: =IF(I7="昭","〇","") | G7: =IF(I7="平","〇","") | H7: =IF(I7="令","〇","") | I7: =IF($N7="","",TEXT($N7,"gg")) | J7: =IF($N7="","",TEXT($N7,"ggg")) | K7: =IF($N7="","",TEXT($N7,"e")) | L7: =IF($N7="","",TEXT($N7,"m")) | M7: =IF($N7="","",TEXT($N7,"d")) | P7: =IFERROR(LEFT(O7,FIND("-",O7)-1),"") | Q7: =IFERROR(RIGHT(O7,LEN(O7)-FIND("-",O7)),"") | R7: =IFERROR(LEFT(Q7,FIND("-",Q7)-1),"") | S7: =IFERROR(RIGHT(Q7,LEN(Q7)-FIND("-",Q7)),"") | U7: =IFERROR(LEFT(T7,FIND("-",T7)-1),"") | V7: =IFERROR(RIGHT(T7,LEN(T7)-FIND("-",T7)),"") | W7: =IFERROR(LEFT(V7,FIND("-",V7)-1),"") | X7: =IFERROR(RIGHT(V7,LEN(V7)-FIND("-",V7)),"") | Z7: =IF(Y7="","",LEFT(SUBSTITUTE(ASC(Y7),"-",""),3)) | AA7: - | AB7: =IF(Y7="","",MID(SUBSTITUTE(ASC(Y7),"-",""),4,4)) | AE7: =IF(AK7="","",TEXT($AK7,"ggg")) | AF7: =IF(AK7="","",TEXT($AK7,"gg")) | AG7: =IF(AK7="","",TEXT($AK7,"g")) | AH7: =IF(AK7="","",TEXT($AK7,"e")) | AI7: =IF(AK7="","",TEXT($AK7,"m")) | AJ7: =IF(AK7="","",TEXT($AK7,"d")) | AL7: =IF(AM7="","",IF(各種設定金額!$B$7="","○○県",各種設定金額!$B$7)) | AO7: =IF(TRIM(AQ7)="","",AP7&AQ7&AR7) | AR7: 号 | AS7: =IF(AY7="","",TEXT($AY7,"ggg")) | AT7: =IF(AY7="","",TEXT($AY7,"gg")) | AU7: =IF(AY7="","",TEXT($AY7,"g")) | AV7: =IF(AY7="","",TEXT($AY7,"e")) | AW7: =IF(AY7="","",TEXT($AY7,"m")) | AX7: =IF(AY7="","",TEXT($AY7,"d")) | AZ7: =IF(BA7="","",IF(各種設定金額!$B$7="","○○県",各種設定金額!$B$7)) | BC7: =IF(TRIM(BE7)="","",BD7&BE7&BF7) | BF7: 号 | BG7: =IF(BM7="","",TEXT($BM7,"ggg")) | BH7: =IF(BM7="","",TEXT($BM7,"gg")) | BI7: =IF(BM7="","",TEXT($BM7,"g")) | BJ7: =IF(BM7="","",TEXT($BM7,"e")) | BK7: =IF(BM7="","",TEXT($BM7,"m")) | BL7: =IF(BM7="","",TEXT($BM7,"d")) | BN7: =IF(BO7="","",IF(各種設定金額!$B$7="","○○県",各種設定金額!$B$7)) | BQ7: =IF(TRIM(BS7)="","",BR7&BS7&BT7) | BT7: 号 | BU7: =IF(CA7="","",TEXT($CA7,"ggg")) | BV7: =IF(CA7="","",TEXT($CA7,"gg")) | BW7: =IF(CA7="","",TEXT($CA7,"g")) | BX7: =IF(CA7="","",TEXT($CA7,"e")) | BY7: =IF(CA7="","",TEXT($CA7,"m")) | BZ7: =IF(CA7="","",TEXT($CA7,"d")) | CB7: =IF(COUNT(AY7,BM7,CA7)=0,"",TEXT(DATE(YEAR(MIN(AY7,BM7,CA7))+3,9,14),"g")) | CC7: =IF(COUNT(AY7,BM7,CA7)=0,"",VALUE(TEXT(DATE(YEAR(MIN(AY7,BM7,CA7))+3,9,14),"e"))) | CH7: =YEAR(TODAY()) -> 2026 | CI7: =TEXT($CO7,"ggg") -> 令和 | CJ7: =TEXT($CO7,"g") -> R | CK7: =TEXT($CO7,"e") -> 8 | CL7: =MONTH(TODAY()) -> 10 | CM7: =DAY(TODAY()) -> 24 | CO7: =TODAY() -> 46319
A8: =IF(B8="","",ROW()-ROW(会員表[#Headers])) | C8: {=_xlfn.LET(_xlpm.s,PHONETIC(B8),_xlpm.c,_xlfn.UNICODE(MID(_xlpm.s,_xlfn.SEQUENCE(LEN(_xlpm.s)),1)),IF(_xlpm.s="","",_xlfn.CONCAT(_xlfn.UNICHAR(_xlpm.c-96*(_xlpm.c>=12449)*(_xlpm.c<=12534)))))} | D8: {=_xlfn.LET(_xlpm.s,PHONETIC(B8),_xlpm.c,_xlfn.UNICODE(MID(_xlpm.s,_xlfn.SEQUENCE(LEN(_xlpm.s)),1)),IF(_xlpm.s="","",_xlfn.CONCAT(_xlfn.UNICHAR(_xlpm.c+96*(_xlpm.c>=12353)*(_xlpm.c<=12438)))))} | E8: =IF(N8="","",DATEDIF(N8,TODAY(),"Y")) | F8: =IF(I8="昭","〇","") | G8: =IF(I8="平","〇","") | H8: =IF(I8="令","〇","") | I8: =IF($N8="","",TEXT($N8,"gg")) | J8: =IF($N8="","",TEXT($N8,"ggg")) | K8: =IF($N8="","",TEXT($N8,"e")) | L8: =IF($N8="","",TEXT($N8,"m")) | M8: =IF($N8="","",TEXT($N8,"d")) | P8: =IFERROR(LEFT(O8,FIND("-",O8)-1),"") | Q8: =IFERROR(RIGHT(O8,LEN(O8)-FIND("-",O8)),"") | R8: =IFERROR(LEFT(Q8,FIND("-",Q8)-1),"") | S8: =IFERROR(RIGHT(Q8,LEN(Q8)-FIND("-",Q8)),"") | U8: =IFERROR(LEFT(T8,FIND("-",T8)-1),"") | V8: =IFERROR(RIGHT(T8,LEN(T8)-FIND("-",T8)),"") | W8: =IFERROR(LEFT(V8,FIND("-",V8)-1),"") | X8: =IFERROR(RIGHT(V8,LEN(V8)-FIND("-",V8)),"") | Z8: =IF(Y8="","",LEFT(SUBSTITUTE(ASC(Y8),"-",""),3)) | AA8: - | AB8: =IF(Y8="","",MID(SUBSTITUTE(ASC(Y8),"-",""),4,4)) | AE8: =IF(AK8="","",TEXT($AK8,"ggg")) | AF8: =IF(AK8="","",TEXT($AK8,"gg")) | AG8: =IF(AK8="","",TEXT($AK8,"g")) | AH8: =IF(AK8="","",TEXT($AK8,"e")) | AI8: =IF(AK8="","",TEXT($AK8,"m")) | AJ8: =IF(AK8="","",TEXT($AK8,"d")) | AL8: =IF(AM8="","",IF(各種設定金額!$B$7="","○○県",各種設定金額!$B$7)) | AO8: =IF(TRIM(AQ8)="","",AP8&AQ8&AR8) | AR8: 号 | AS8: =IF(AY8="","",TEXT($AY8,"ggg")) | AT8: =IF(AY8="","",TEXT($AY8,"gg")) | AU8: =IF(AY8="","",TEXT($AY8,"g")) | AV8: =IF(AY8="","",TEXT($AY8,"e")) | AW8: =IF(AY8="","",TEXT($AY8,"m")) | AX8: =IF(AY8="","",TEXT($AY8,"d")) | AZ8: =IF(BA8="","",IF(各種設定金額!$B$7="","○○県",各種設定金額!$B$7)) | BC8: =IF(TRIM(BE8)="","",BD8&BE8&BF8) | BF8: 号 | BG8: =IF(BM8="","",TEXT($BM8,"ggg")) | BH8: =IF(BM8="","",TEXT($BM8,"gg")) | BI8: =IF(BM8="","",TEXT($BM8,"g")) | BJ8: =IF(BM8="","",TEXT($BM8,"e")) | BK8: =IF(BM8="","",TEXT($BM8,"m")) | BL8: =IF(BM8="","",TEXT($BM8,"d")) | BN8: =IF(BO8="","",IF(各種設定金額!$B$7="","○○県",各種設定金額!$B$7)) | BQ8: =IF(TRIM(BS8)="","",BR8&BS8&BT8) | BT8: 号 | BU8: =IF(CA8="","",TEXT($CA8,"ggg")) | BV8: =IF(CA8="","",TEXT($CA8,"gg")) | BW8: =IF(CA8="","",TEXT($CA8,"g")) | BX8: =IF(CA8="","",TEXT($CA8,"e")) | BY8: =IF(CA8="","",TEXT($CA8,"m")) | BZ8: =IF(CA8="","",TEXT($CA8,"d")) | CB8: =IF(COUNT(AY8,BM8,CA8)=0,"",TEXT(DATE(YEAR(MIN(AY8,BM8,CA8))+3,9,14),"g")) | CC8: =IF(COUNT(AY8,BM8,CA8)=0,"",VALUE(TEXT(DATE(YEAR(MIN(AY8,BM8,CA8))+3,9,14),"e"))) | CH8: =YEAR(TODAY()) -> 2026 | CI8: =TEXT($CO8,"ggg") -> 令和 | CJ8: =TEXT($CO8,"g") -> R | CK8: =TEXT($CO8,"e") -> 8 | CL8: =MONTH(TODAY()) -> 10 | CM8: =DAY(TODAY()) -> 24 | CO8: =TODAY() -> 46319
A9: =IF(B9="","",ROW()-ROW(会員表[#Headers])) | C9: {=_xlfn.LET(_xlpm.s,PHONETIC(B9),_xlpm.c,_xlfn.UNICODE(MID(_xlpm.s,_xlfn.SEQUENCE(LEN(_xlpm.s)),1)),IF(_xlpm.s="","",_xlfn.CONCAT(_xlfn.UNICHAR(_xlpm.c-96*(_xlpm.c>=12449)*(_xlpm.c<=12534)))))} | D9: {=_xlfn.LET(_xlpm.s,PHONETIC(B9),_xlpm.c,_xlfn.UNICODE(MID(_xlpm.s,_xlfn.SEQUENCE(LEN(_xlpm.s)),1)),IF(_xlpm.s="","",_xlfn.CONCAT(_xlfn.UNICHAR(_xlpm.c+96*(_xlpm.c>=12353)*(_xlpm.c<=12438)))))} | E9: =IF(N9="","",DATEDIF(N9,TODAY(),"Y")) | F9: =IF(I9="昭","〇","") | G9: =IF(I9="平","〇","") | H9: =IF(I9="令","〇","") | I9: =IF($N9="","",TEXT($N9,"gg")) | J9: =IF($N9="","",TEXT($N9,"ggg")) | K9: =IF($N9="","",TEXT($N9,"e")) | L9: =IF($N9="","",TEXT($N9,"m")) | M9: =IF($N9="","",TEXT($N9,"d")) | P9: =IFERROR(LEFT(O9,FIND("-",O9)-1),"") | Q9: =IFERROR(RIGHT(O9,LEN(O9)-FIND("-",O9)),"") | R9: =IFERROR(LEFT(Q9,FIND("-",Q9)-1),"") | S9: =IFERROR(RIGHT(Q9,LEN(Q9)-FIND("-",Q9)),"") | U9: =IFERROR(LEFT(T9,FIND("-",T9)-1),"") | V9: =IFERROR(RIGHT(T9,LEN(T9)-FIND("-",T9)),"") | W9: =IFERROR(LEFT(V9,FIND("-",V9)-1),"") | X9: =IFERROR(RIGHT(V9,LEN(V9)-FIND("-",V9)),"") | Z9: =IF(Y9="","",LEFT(SUBSTITUTE(ASC(Y9),"-",""),3)) | AA9: - | AB9: =IF(Y9="","",MID(SUBSTITUTE(ASC(Y9),"-",""),4,4)) | AE9: =IF(AK9="","",TEXT($AK9,"ggg")) | AF9: =IF(AK9="","",TEXT($AK9,"gg")) | AG9: =IF(AK9="","",TEXT($AK9,"g")) | AH9: =IF(AK9="","",TEXT($AK9,"e")) | AI9: =IF(AK9="","",TEXT($AK9,"m")) | AJ9: =IF(AK9="","",TEXT($AK9,"d")) | AL9: =IF(AM9="","",IF(各種設定金額!$B$7="","○○県",各種設定金額!$B$7)) | AO9: =IF(TRIM(AQ9)="","",AP9&AQ9&AR9) | AR9: 号 | AS9: =IF(AY9="","",TEXT($AY9,"ggg")) | AT9: =IF(AY9="","",TEXT($AY9,"gg")) | AU9: =IF(AY9="","",TEXT($AY9,"g")) | AV9: =IF(AY9="","",TEXT($AY9,"e")) | AW9: =IF(AY9="","",TEXT($AY9,"m")) | AX9: =IF(AY9="","",TEXT($AY9,"d")) | AZ9: =IF(BA9="","",IF(各種設定金額!$B$7="","○○県",各種設定金額!$B$7)) | BC9: =IF(TRIM(BE9)="","",BD9&BE9&BF9) | BF9: 号 | BG9: =IF(BM9="","",TEXT($BM9,"ggg")) | BH9: =IF(BM9="","",TEXT($BM9,"gg")) | BI9: =IF(BM9="","",TEXT($BM9,"g")) | BJ9: =IF(BM9="","",TEXT($BM9,"e")) | BK9: =IF(BM9="","",TEXT($BM9,"m")) | BL9: =IF(BM9="","",TEXT($BM9,"d")) | BN9: =IF(BO9="","",IF(各種設定金額!$B$7="","○○県",各種設定金額!$B$7)) | BQ9: =IF(TRIM(BS9)="","",BR9&BS9&BT9) | BT9: 号 | BU9: =IF(CA9="","",TEXT($CA9,"ggg")) | BV9: =IF(CA9="","",TEXT($CA9,"gg")) | BW9: =IF(CA9="","",TEXT($CA9,"g")) | BX9: =IF(CA9="","",TEXT($CA9,"e")) | BY9: =IF(CA9="","",TEXT($CA9,"m")) | BZ9: =IF(CA9="","",TEXT($CA9,"d")) | CB9: =IF(COUNT(AY9,BM9,CA9)=0,"",TEXT(DATE(YEAR(MIN(AY9,BM9,CA9))+3,9,14),"g")) | CC9: =IF(COUNT(AY9,BM9,CA9)=0,"",VALUE(TEXT(DATE(YEAR(MIN(AY9,BM9,CA9))+3,9,14),"e"))) | CH9: =YEAR(TODAY()) -> 2026 | CI9: =TEXT($CO9,"ggg") -> 令和 | CJ9: =TEXT($CO9,"g") -> R | CK9: =TEXT($CO9,"e") -> 8 | CL9: =MONTH(TODAY()) -> 10 | CM9: =DAY(TODAY()) -> 24 | CO9: =TODAY() -> 46319
A10: =IF(B10="","",ROW()-ROW(会員表[#Headers])) | C10: {=_xlfn.LET(_xlpm.s,PHONETIC(B10),_xlpm.c,_xlfn.UNICODE(MID(_xlpm.s,_xlfn.SEQUENCE(LEN(_xlpm.s)),1)),IF(_xlpm.s="","",_xlfn.CONCAT(_xlfn.UNICHAR(_xlpm.c-96*(_xlpm.c>=12449)*(_xlpm.c<=12534)))))} | D10: {=_xlfn.LET(_xlpm.s,PHONETIC(B10),_xlpm.c,_xlfn.UNICODE(MID(_xlpm.s,_xlfn.SEQUENCE(LEN(_xlpm.s)),1)),IF(_xlpm.s="","",_xlfn.CONCAT(_xlfn.UNICHAR(_xlpm.c+96*(_xlpm.c>=12353)*(_xlpm.c<=12438)))))} | E10: =IF(N10="","",DATEDIF(N10,TODAY(),"Y")) | F10: =IF(I10="昭","〇","") | G10: =IF(I10="平","〇","") | H10: =IF(I10="令","〇","") | I10: =IF($N10="","",TEXT($N10,"gg")) | J10: =IF($N10="","",TEXT($N10,"ggg")) | K10: =IF($N10="","",TEXT($N10,"e")) | L10: =IF($N10="","",TEXT($N10,"m")) | M10: =IF($N10="","",TEXT($N10,"d")) | P10: =IFERROR(LEFT(O10,FIND("-",O10)-1),"") | Q10: =IFERROR(RIGHT(O10,LEN(O10)-FIND("-",O10)),"") | R10: =IFERROR(LEFT(Q10,FIND("-",Q10)-1),"") | S10: =IFERROR(RIGHT(Q10,LEN(Q10)-FIND("-",Q10)),"") | U10: =IFERROR(LEFT(T10,FIND("-",T10)-1),"") | V10: =IFERROR(RIGHT(T10,LEN(T10)-FIND("-",T10)),"") | W10: =IFERROR(LEFT(V10,FIND("-",V10)-1),"") | X10: =IFERROR(RIGHT(V10,LEN(V10)-FIND("-",V10)),"") | Z10: =IF(Y10="","",LEFT(SUBSTITUTE(ASC(Y10),"-",""),3)) | AA10: - | AB10: =IF(Y10="","",MID(SUBSTITUTE(ASC(Y10),"-",""),4,4)) | AE10: =IF(AK10="","",TEXT($AK10,"ggg")) | AF10: =IF(AK10="","",TEXT($AK10,"gg")) | AG10: =IF(AK10="","",TEXT($AK10,"g")) | AH10: =IF(AK10="","",TEXT($AK10,"e")) | AI10: =IF(AK10="","",TEXT($AK10,"m")) | AJ10: =IF(AK10="","",TEXT($AK10,"d")) | AL10: =IF(AM10="","",IF(各種設定金額!$B$7="","○○県",各種設定金額!$B$7)) | AO10: =IF(TRIM(AQ10)="","",AP10&AQ10&AR10) | AR10: 号 | AS10: =IF(AY10="","",TEXT($AY10,"ggg")) | AT10: =IF(AY10="","",TEXT($AY10,"gg")) | AU10: =IF(AY10="","",TEXT($AY10,"g")) | AV10: =IF(AY10="","",TEXT($AY10,"e")) | AW10: =IF(AY10="","",TEXT($AY10,"m")) | AX10: =IF(AY10="","",TEXT($AY10,"d")) | AZ10: =IF(BA10="","",IF(各種設定金額!$B$7="","○○県",各種設定金額!$B$7)) | BC10: =IF(TRIM(BE10)="","",BD10&BE10&BF10) | BF10: 号 | BG10: =IF(BM10="","",TEXT($BM10,"ggg")) | BH10: =IF(BM10="","",TEXT($BM10,"gg")) | BI10: =IF(BM10="","",TEXT($BM10,"g")) | BJ10: =IF(BM10="","",TEXT($BM10,"e")) | BK10: =IF(BM10="","",TEXT($BM10,"m")) | BL10: =IF(BM10="","",TEXT($BM10,"d")) | BN10: =IF(BO10="","",IF(各種設定金額!$B$7="","○○県",各種設定金額!$B$7)) | BQ10: =IF(TRIM(BS10)="","",BR10&BS10&BT10) | BT10: 号 | BU10: =IF(CA10="","",TEXT($CA10,"ggg")) | BV10: =IF(CA10="","",TEXT($CA10,"gg")) | BW10: =IF(CA10="","",TEXT($CA10,"g")) | BX10: =IF(CA10="","",TEXT($CA10,"e")) | BY10: =IF(CA10="","",TEXT($CA10,"m")) | BZ10: =IF(CA10="","",TEXT($CA10,"d")) | CB10: =IF(COUNT(AY10,BM10,CA10)=0,"",TEXT(DATE(YEAR(MIN(AY10,BM10,CA10))+3,9,14),"g")) | CC10: =IF(COUNT(AY10,BM10,CA10)=0,"",VALUE(TEXT(DATE(YEAR(MIN(AY10,BM10,CA10))+3,9,14),"e"))) | CH10: =YEAR(TODAY()) -> 2026 | CI10: =TEXT($CO10,"ggg") -> 令和 | CJ10: =TEXT($CO10,"g") -> R | CK10: =TEXT($CO10,"e") -> 8 | CL10: =MONTH(TODAY()) -> 10 | CM10: =DAY(TODAY()) -> 24 | CO10: =TODAY() -> 46319
A11: =IF(B11="","",ROW()-ROW(会員表[#Headers])) | C11: {=_xlfn.LET(_xlpm.s,PHONETIC(B11),_xlpm.c,_xlfn.UNICODE(MID(_xlpm.s,_xlfn.SEQUENCE(LEN(_xlpm.s)),1)),IF(_xlpm.s="","",_xlfn.CONCAT(_xlfn.UNICHAR(_xlpm.c-96*(_xlpm.c>=12449)*(_xlpm.c<=12534)))))} | D11: {=_xlfn.LET(_xlpm.s,PHONETIC(B11),_xlpm.c,_xlfn.UNICODE(MID(_xlpm.s,_xlfn.SEQUENCE(LEN(_xlpm.s)),1)),IF(_xlpm.s="","",_xlfn.CONCAT(_xlfn.UNICHAR(_xlpm.c+96*(_xlpm.c>=12353)*(_xlpm.c<=12438)))))} | E11: =IF(N11="","",DATEDIF(N11,TODAY(),"Y")) | F11: =IF(I11="昭","〇","") | G11: =IF(I11="平","〇","") | H11: =IF(I11="令","〇","") | I11: =IF($N11="","",TEXT($N11,"gg")) | J11: =IF($N11="","",TEXT($N11,"ggg")) | K11: =IF($N11="","",TEXT($N11,"e")) | L11: =IF($N11="","",TEXT($N11,"m")) | M11: =IF($N11="","",TEXT($N11,"d")) | P11: =IFERROR(LEFT(O11,FIND("-",O11)-1),"") | Q11: =IFERROR(RIGHT(O11,LEN(O11)-FIND("-",O11)),"") | R11: =IFERROR(LEFT(Q11,FIND("-",Q11)-1),"") | S11: =IFERROR(RIGHT(Q11,LEN(Q11)-FIND("-",Q11)),"") | U11: =IFERROR(LEFT(T11,FIND("-",T11)-1),"") | V11: =IFERROR(RIGHT(T11,LEN(T11)-FIND("-",T11)),"") | W11: =IFERROR(LEFT(V11,FIND("-",V11)-1),"") | X11: =IFERROR(RIGHT(V11,LEN(V11)-FIND("-",V11)),"") | Z11: =IF(Y11="","",LEFT(SUBSTITUTE(ASC(Y11),"-",""),3)) | AA11: - | AB11: =IF(Y11="","",MID(SUBSTITUTE(ASC(Y11),"-",""),4,4)) | AE11: =IF(AK11="","",TEXT($AK11,"ggg")) | AF11: =IF(AK11="","",TEXT($AK11,"gg")) | AG11: =IF(AK11="","",TEXT($AK11,"g")) | AH11: =IF(AK11="","",TEXT($AK11,"e")) | AI11: =IF(AK11="","",TEXT($AK11,"m")) | AJ11: =IF(AK11="","",TEXT($AK11,"d")) | AL11: =IF(AM11="","",IF(各種設定金額!$B$7="","○○県",各種設定金額!$B$7)) | AO11: =IF(TRIM(AQ11)="","",AP11&AQ11&AR11) | AR11: 号 | AS11: =IF(AY11="","",TEXT($AY11,"ggg")) | AT11: =IF(AY11="","",TEXT($AY11,"gg")) | AU11: =IF(AY11="","",TEXT($AY11,"g")) | AV11: =IF(AY11="","",TEXT($AY11,"e")) | AW11: =IF(AY11="","",TEXT($AY11,"m")) | AX11: =IF(AY11="","",TEXT($AY11,"d")) | AZ11: =IF(BA11="","",IF(各種設定金額!$B$7="","○○県",各種設定金額!$B$7)) | BC11: =IF(TRIM(BE11)="","",BD11&BE11&BF11) | BF11: 号 | BG11: =IF(BM11="","",TEXT($BM11,"ggg")) | BH11: =IF(BM11="","",TEXT($BM11,"gg")) | BI11: =IF(BM11="","",TEXT($BM11,"g")) | BJ11: =IF(BM11="","",TEXT($BM11,"e")) | BK11: =IF(BM11="","",TEXT($BM11,"m")) | BL11: =IF(BM11="","",TEXT($BM11,"d")) | BN11: =IF(BO11="","",IF(各種設定金額!$B$7="","○○県",各種設定金額!$B$7)) | BQ11: =IF(TRIM(BS11)="","",BR11&BS11&BT11) | BT11: 号 | BU11: =IF(CA11="","",TEXT($CA11,"ggg")) | BV11: =IF(CA11="","",TEXT($CA11,"gg")) | BW11: =IF(CA11="","",TEXT($CA11,"g")) | BX11: =IF(CA11="","",TEXT($CA11,"e")) | BY11: =IF(CA11="","",TEXT($CA11,"m")) | BZ11: =IF(CA11="","",TEXT($CA11,"d")) | CB11: =IF(COUNT(AY11,BM11,CA11)=0,"",TEXT(DATE(YEAR(MIN(AY11,BM11,CA11))+3,9,14),"g")) | CC11: =IF(COUNT(AY11,BM11,CA11)=0,"",VALUE(TEXT(DATE(YEAR(MIN(AY11,BM11,CA11))+3,9,14),"e"))) | CH11: =YEAR(TODAY()) -> 2026 | CI11: =TEXT($CO11,"ggg") -> 令和 | CJ11: =TEXT($CO11,"g") -> R | CK11: =TEXT($CO11,"e") -> 8 | CL11: =MONTH(TODAY()) -> 10 | CM11: =DAY(TODAY()) -> 24 | CO11: =TODAY() -> 46319
A12: =IF(B12="","",ROW()-ROW(会員表[#Headers])) | C12: {=_xlfn.LET(_xlpm.s,PHONETIC(B12),_xlpm.c,_xlfn.UNICODE(MID(_xlpm.s,_xlfn.SEQUENCE(LEN(_xlpm.s)),1)),IF(_xlpm.s="","",_xlfn.CONCAT(_xlfn.UNICHAR(_xlpm.c-96*(_xlpm.c>=12449)*(_xlpm.c<=12534)))))} | D12: {=_xlfn.LET(_xlpm.s,PHONETIC(B12),_xlpm.c,_xlfn.UNICODE(MID(_xlpm.s,_xlfn.SEQUENCE(LEN(_xlpm.s)),1)),IF(_xlpm.s="","",_xlfn.CONCAT(_xlfn.UNICHAR(_xlpm.c+96*(_xlpm.c>=12353)*(_xlpm.c<=12438)))))} | E12: =IF(N12="","",DATEDIF(N12,TODAY(),"Y")) | F12: =IF(I12="昭","〇","") | G12: =IF(I12="平","〇","") | H12: =IF(I12="令","〇","") | I12: =IF($N12="","",TEXT($N12,"gg")) | J12: =IF($N12="","",TEXT($N12,"ggg")) | K12: =IF($N12="","",TEXT($N12,"e")) | L12: =IF($N12="","",TEXT($N12,"m")) | M12: =IF($N12="","",TEXT($N12,"d")) | P12: =IFERROR(LEFT(O12,FIND("-",O12)-1),"") | Q12: =IFERROR(RIGHT(O12,LEN(O12)-FIND("-",O12)),"") | R12: =IFERROR(LEFT(Q12,FIND("-",Q12)-1),"") | S12: =IFERROR(RIGHT(Q12,LEN(Q12)-FIND("-",Q12)),"") | U12: =IFERROR(LEFT(T12,FIND("-",T12)-1),"") | V12: =IFERROR(RIGHT(T12,LEN(T12)-FIND("-",T12)),"") | W12: =IFERROR(LEFT(V12,FIND("-",V12)-1),"") | X12: =IFERROR(RIGHT(V12,LEN(V12)-FIND("-",V12)),"") | Z12: =IF(Y12="","",LEFT(SUBSTITUTE(ASC(Y12),"-",""),3)) | AA12: - | AB12: =IF(Y12="","",MID(SUBSTITUTE(ASC(Y12),"-",""),4,4)) | AE12: =IF(AK12="","",TEXT($AK12,"ggg")) | AF12: =IF(AK12="","",TEXT($AK12,"gg")) | AG12: =IF(AK12="","",TEXT($AK12,"g")) | AH12: =IF(AK12="","",TEXT($AK12,"e")) | AI12: =IF(AK12="","",TEXT($AK12,"m")) | AJ12: =IF(AK12="","",TEXT($AK12,"d")) | AL12: =IF(AM12="","",IF(各種設定金額!$B$7="","○○県",各種設定金額!$B$7)) | AO12: =IF(TRIM(AQ12)="","",AP12&AQ12&AR12) | AR12: 号 | AS12: =IF(AY12="","",TEXT($AY12,"ggg")) | AT12: =IF(AY12="","",TEXT($AY12,"gg")) | AU12: =IF(AY12="","",TEXT($AY12,"g")) | AV12: =IF(AY12="","",TEXT($AY12,"e")) | AW12: =IF(AY12="","",TEXT($AY12,"m")) | AX12: =IF(AY12="","",TEXT($AY12,"d")) | AZ12: =IF(BA12="","",IF(各種設定金額!$B$7="","○○県",各種設定金額!$B$7)) | BC12: =IF(TRIM(BE12)="","",BD12&BE12&BF12) | BF12: 号 | BG12: =IF(BM12="","",TEXT($BM12,"ggg")) | BH12: =IF(BM12="","",TEXT($BM12,"gg")) | BI12: =IF(BM12="","",TEXT($BM12,"g")) | BJ12: =IF(BM12="","",TEXT($BM12,"e")) | BK12: =IF(BM12="","",TEXT($BM12,"m")) | BL12: =IF(BM12="","",TEXT($BM12,"d")) | BN12: =IF(BO12="","",IF(各種設定金額!$B$7="","○○県",各種設定金額!$B$7)) | BQ12: =IF(TRIM(BS12)="","",BR12&BS12&BT12) | BT12: 号 | BU12: =IF(CA12="","",TEXT($CA12,"ggg")) | BV12: =IF(CA12="","",TEXT($CA12,"gg")) | BW12: =IF(CA12="","",TEXT($CA12,"g")) | BX12: =IF(CA12="","",TEXT($CA12,"e")) | BY12: =IF(CA12="","",TEXT($CA12,"m")) | BZ12: =IF(CA12="","",TEXT($CA12,"d")) | CB12: =IF(COUNT(AY12,BM12,CA12)=0,"",TEXT(DATE(YEAR(MIN(AY12,BM12,CA12))+3,9,14),"g")) | CC12: =IF(COUNT(AY12,BM12,CA12)=0,"",VALUE(TEXT(DATE(YEAR(MIN(AY12,BM12,CA12))+3,9,14),"e"))) | CH12: =YEAR(TODAY()) -> 2026 | CI12: =TEXT($CO12,"ggg") -> 令和 | CJ12: =TEXT($CO12,"g") -> R | CK12: =TEXT($CO12,"e") -> 8 | CL12: =MONTH(TODAY()) -> 10 | CM12: =DAY(TODAY()) -> 24 | CO12: =TODAY() -> 46319
A13: =IF(B13="","",ROW()-ROW(会員表[#Headers])) | C13: {=_xlfn.LET(_xlpm.s,PHONETIC(B13),_xlpm.c,_xlfn.UNICODE(MID(_xlpm.s,_xlfn.SEQUENCE(LEN(_xlpm.s)),1)),IF(_xlpm.s="","",_xlfn.CONCAT(_xlfn.UNICHAR(_xlpm.c-96*(_xlpm.c>=12449)*(_xlpm.c<=12534)))))} | D13: {=_xlfn.LET(_xlpm.s,PHONETIC(B13),_xlpm.c,_xlfn.UNICODE(MID(_xlpm.s,_xlfn.SEQUENCE(LEN(_xlpm.s)),1)),IF(_xlpm.s="","",_xlfn.CONCAT(_xlfn.UNICHAR(_xlpm.c+96*(_xlpm.c>=12353)*(_xlpm.c<=12438)))))} | E13: =IF(N13="","",DATEDIF(N13,TODAY(),"Y")) | F13: =IF(I13="昭","〇","") | G13: =IF(I13="平","〇","") | H13: =IF(I13="令","〇","") | I13: =IF($N13="","",TEXT($N13,"gg")) | J13: =IF($N13="","",TEXT($N13,"ggg")) | K13: =IF($N13="","",TEXT($N13,"e")) | L13: =IF($N13="","",TEXT($N13,"m")) | M13: =IF($N13="","",TEXT($N13,"d")) | P13: =IFERROR(LEFT(O13,FIND("-",O13)-1),"") | Q13: =IFERROR(RIGHT(O13,LEN(O13)-FIND("-",O13)),"") | R13: =IFERROR(LEFT(Q13,FIND("-",Q13)-1),"") | S13: =IFERROR(RIGHT(Q13,LEN(Q13)-FIND("-",Q13)),"") | U13: =IFERROR(LEFT(T13,FIND("-",T13)-1),"") | V13: =IFERROR(RIGHT(T13,LEN(T13)-FIND("-",T13)),"") | W13: =IFERROR(LEFT(V13,FIND("-",V13)-1),"") | X13: =IFERROR(RIGHT(V13,LEN(V13)-FIND("-",V13)),"") | Z13: =IF(Y13="","",LEFT(SUBSTITUTE(ASC(Y13),"-",""),3)) | AA13: - | AB13: =IF(Y13="","",MID(SUBSTITUTE(ASC(Y13),"-",""),4,4)) | AE13: =IF(AK13="","",TEXT($AK13,"ggg")) | AF13: =IF(AK13="","",TEXT($AK13,"gg")) | AG13: =IF(AK13="","",TEXT($AK13,"g")) | AH13: =IF(AK13="","",TEXT($AK13,"e")) | AI13: =IF(AK13="","",TEXT($AK13,"m")) | AJ13: =IF(AK13="","",TEXT($AK13,"d")) | AL13: =IF(AM13="","",IF(各種設定金額!$B$7="","○○県",各種設定金額!$B$7)) | AO13: =IF(TRIM(AQ13)="","",AP13&AQ13&AR13) | AR13: 号 | AS13: =IF(AY13="","",TEXT($AY13,"ggg")) | AT13: =IF(AY13="","",TEXT($AY13,"gg")) | AU13: =IF(AY13="","",TEXT($AY13,"g")) | AV13: =IF(AY13="","",TEXT($AY13,"e")) | AW13: =IF(AY13="","",TEXT($AY13,"m")) | AX13: =IF(AY13="","",TEXT($AY13,"d")) | AZ13: =IF(BA13="","",IF(各種設定金額!$B$7="","○○県",各種設定金額!$B$7)) | BC13: =IF(TRIM(BE13)="","",BD13&BE13&BF13) | BF13: 号 | BG13: =IF(BM13="","",TEXT($BM13,"ggg")) | BH13: =IF(BM13="","",TEXT($BM13,"gg")) | BI13: =IF(BM13="","",TEXT($BM13,"g")) | BJ13: =IF(BM13="","",TEXT($BM13,"e")) | BK13: =IF(BM13="","",TEXT($BM13,"m")) | BL13: =IF(BM13="","",TEXT($BM13,"d")) | BN13: =IF(BO13="","",IF(各種設定金額!$B$7="","○○県",各種設定金額!$B$7)) | BQ13: =IF(TRIM(BS13)="","",BR13&BS13&BT13) | BT13: 号 | BU13: =IF(CA13="","",TEXT($CA13,"ggg")) | BV13: =IF(CA13="","",TEXT($CA13,"gg")) | BW13: =IF(CA13="","",TEXT($CA13,"g")) | BX13: =IF(CA13="","",TEXT($CA13,"e")) | BY13: =IF(CA13="","",TEXT($CA13,"m")) | BZ13: =IF(CA13="","",TEXT($CA13,"d")) | CB13: =IF(COUNT(AY13,BM13,CA13)=0,"",TEXT(DATE(YEAR(MIN(AY13,BM13,CA13))+3,9,14),"g")) | CC13: =IF(COUNT(AY13,BM13,CA13)=0,"",VALUE(TEXT(DATE(YEAR(MIN(AY13,BM13,CA13))+3,9,14),"e"))) | CH13: =YEAR(TODAY()) -> 2026 | CI13: =TEXT($CO13,"ggg") -> 令和 | CJ13: =TEXT($CO13,"g") -> R | CK13: =TEXT($CO13,"e") -> 8 | CL13: =MONTH(TODAY()) -> 10 | CM13: =DAY(TODAY()) -> 24 | CO13: =TODAY() -> 46319
A14: =IF(B14="","",ROW()-ROW(会員表[#Headers])) | C14: {=_xlfn.LET(_xlpm.s,PHONETIC(B14),_xlpm.c,_xlfn.UNICODE(MID(_xlpm.s,_xlfn.SEQUENCE(LEN(_xlpm.s)),1)),IF(_xlpm.s="","",_xlfn.CONCAT(_xlfn.UNICHAR(_xlpm.c-96*(_xlpm.c>=12449)*(_xlpm.c<=12534)))))} | D14: {=_xlfn.LET(_xlpm.s,PHONETIC(B14),_xlpm.c,_xlfn.UNICODE(MID(_xlpm.s,_xlfn.SEQUENCE(LEN(_xlpm.s)),1)),IF(_xlpm.s="","",_xlfn.CONCAT(_xlfn.UNICHAR(_xlpm.c+96*(_xlpm.c>=12353)*(_xlpm.c<=12438)))))} | E14: =IF(N14="","",DATEDIF(N14,TODAY(),"Y")) | F14: =IF(I14="昭","〇","") | G14: =IF(I14="平","〇","") | H14: =IF(I14="令","〇","") | I14: =IF($N14="","",TEXT($N14,"gg")) | J14: =IF($N14="","",TEXT($N14,"ggg")) | K14: =IF($N14="","",TEXT($N14,"e")) | L14: =IF($N14="","",TEXT($N14,"m")) | M14: =IF($N14="","",TEXT($N14,"d")) | P14: =IFERROR(LEFT(O14,FIND("-",O14)-1),"") | Q14: =IFERROR(RIGHT(O14,LEN(O14)-FIND("-",O14)),"") | R14: =IFERROR(LEFT(Q14,FIND("-",Q14)-1),"") | S14: =IFERROR(RIGHT(Q14,LEN(Q14)-FIND("-",Q14)),"") | U14: =IFERROR(LEFT(T14,FIND("-",T14)-1),"") | V14: =IFERROR(RIGHT(T14,LEN(T14)-FIND("-",T14)),"") | W14: =IFERROR(LEFT(V14,FIND("-",V14)-1),"") | X14: =IFERROR(RIGHT(V14,LEN(V14)-FIND("-",V14)),"") | Z14: =IF(Y14="","",LEFT(SUBSTITUTE(ASC(Y14),"-",""),3)) | AA14: - | AB14: =IF(Y14="","",MID(SUBSTITUTE(ASC(Y14),"-",""),4,4)) | AE14: =IF(AK14="","",TEXT($AK14,"ggg")) | AF14: =IF(AK14="","",TEXT($AK14,"gg")) | AG14: =IF(AK14="","",TEXT($AK14,"g")) | AH14: =IF(AK14="","",TEXT($AK14,"e")) | AI14: =IF(AK14="","",TEXT($AK14,"m")) | AJ14: =IF(AK14="","",TEXT($AK14,"d")) | AL14: =IF(AM14="","",IF(各種設定金額!$B$7="","○○県",各種設定金額!$B$7)) | AO14: =IF(TRIM(AQ14)="","",AP14&AQ14&AR14) | AR14: 号 | AS14: =IF(AY14="","",TEXT($AY14,"ggg")) | AT14: =IF(AY14="","",TEXT($AY14,"gg")) | AU14: =IF(AY14="","",TEXT($AY14,"g")) | AV14: =IF(AY14="","",TEXT($AY14,"e")) | AW14: =IF(AY14="","",TEXT($AY14,"m")) | AX14: =IF(AY14="","",TEXT($AY14,"d")) | AZ14: =IF(BA14="","",IF(各種設定金額!$B$7="","○○県",各種設定金額!$B$7)) | BC14: =IF(TRIM(BE14)="","",BD14&BE14&BF14) | BF14: 号 | BG14: =IF(BM14="","",TEXT($BM14,"ggg")) | BH14: =IF(BM14="","",TEXT($BM14,"gg")) | BI14: =IF(BM14="","",TEXT($BM14,"g")) | BJ14: =IF(BM14="","",TEXT($BM14,"e")) | BK14: =IF(BM14="","",TEXT($BM14,"m")) | BL14: =IF(BM14="","",TEXT($BM14,"d")) | BN14: =IF(BO14="","",IF(各種設定金額!$B$7="","○○県",各種設定金額!$B$7)) | BQ14: =IF(TRIM(BS14)="","",BR14&BS14&BT14) | BT14: 号 | BU14: =IF(CA14="","",TEXT($CA14,"ggg")) | BV14: =IF(CA14="","",TEXT($CA14,"gg")) | BW14: =IF(CA14="","",TEXT($CA14,"g")) | BX14: =IF(CA14="","",TEXT($CA14,"e")) | BY14: =IF(CA14="","",TEXT($CA14,"m")) | BZ14: =IF(CA14="","",TEXT($CA14,"d")) | CB14: =IF(COUNT(AY14,BM14,CA14)=0,"",TEXT(DATE(YEAR(MIN(AY14,BM14,CA14))+3,9,14),"g")) | CC14: =IF(COUNT(AY14,BM14,CA14)=0,"",VALUE(TEXT(DATE(YEAR(MIN(AY14,BM14,CA14))+3,9,14),"e"))) | CH14: =YEAR(TODAY()) -> 2026 | CI14: =TEXT($CO14,"ggg") -> 令和 | CJ14: =TEXT($CO14,"g") -> R | CK14: =TEXT($CO14,"e") -> 8 | CL14: =MONTH(TODAY()) -> 10 | CM14: =DAY(TODAY()) -> 24 | CO14: =TODAY() -> 46319
A15: =IF(B15="","",ROW()-ROW(会員表[#Headers])) | C15: {=_xlfn.LET(_xlpm.s,PHONETIC(B15),_xlpm.c,_xlfn.UNICODE(MID(_xlpm.s,_xlfn.SEQUENCE(LEN(_xlpm.s)),1)),IF(_xlpm.s="","",_xlfn.CONCAT(_xlfn.UNICHAR(_xlpm.c-96*(_xlpm.c>=12449)*(_xlpm.c<=12534)))))} | D15: {=_xlfn.LET(_xlpm.s,PHONETIC(B15),_xlpm.c,_xlfn.UNICODE(MID(_xlpm.s,_xlfn.SEQUENCE(LEN(_xlpm.s)),1)),IF(_xlpm.s="","",_xlfn.CONCAT(_xlfn.UNICHAR(_xlpm.c+96*(_xlpm.c>=12353)*(_xlpm.c<=12438)))))} | E15: =IF(N15="","",DATEDIF(N15,TODAY(),"Y")) | F15: =IF(I15="昭","〇","") | G15: =IF(I15="平","〇","") | H15: =IF(I15="令","〇","") | I15: =IF($N15="","",TEXT($N15,"gg")) | J15: =IF($N15="","",TEXT($N15,"ggg")) | K15: =IF($N15="","",TEXT($N15,"e")) | L15: =IF($N15="","",TEXT($N15,"m")) | M15: =IF($N15="","",TEXT($N15,"d")) | P15: =IFERROR(LEFT(O15,FIND("-",O15)-1),"") | Q15: =IFERROR(RIGHT(O15,LEN(O15)-FIND("-",O15)),"") | R15: =IFERROR(LEFT(Q15,FIND("-",Q15)-1),"") | S15: =IFERROR(RIGHT(Q15,LEN(Q15)-FIND("-",Q15)),"") | U15: =IFERROR(LEFT(T15,FIND("-",T15)-1),"") | V15: =IFERROR(RIGHT(T15,LEN(T15)-FIND("-",T15)),"") | W15: =IFERROR(LEFT(V15,FIND("-",V15)-1),"") | X15: =IFERROR(RIGHT(V15,LEN(V15)-FIND("-",V15)),"") | Z15: =IF(Y15="","",LEFT(SUBSTITUTE(ASC(Y15),"-",""),3)) | AA15: - | AB15: =IF(Y15="","",MID(SUBSTITUTE(ASC(Y15),"-",""),4,4)) | AE15: =IF(AK15="","",TEXT($AK15,"ggg")) | AF15: =IF(AK15="","",TEXT($AK15,"gg")) | AG15: =IF(AK15="","",TEXT($AK15,"g")) | AH15: =IF(AK15="","",TEXT($AK15,"e")) | AI15: =IF(AK15="","",TEXT($AK15,"m")) | AJ15: =IF(AK15="","",TEXT($AK15,"d")) | AL15: =IF(AM15="","",IF(各種設定金額!$B$7="","○○県",各種設定金額!$B$7)) | AO15: =IF(TRIM(AQ15)="","",AP15&AQ15&AR15) | AR15: 号 | AS15: =IF(AY15="","",TEXT($AY15,"ggg")) | AT15: =IF(AY15="","",TEXT($AY15,"gg")) | AU15: =IF(AY15="","",TEXT($AY15,"g")) | AV15: =IF(AY15="","",TEXT($AY15,"e")) | AW15: =IF(AY15="","",TEXT($AY15,"m")) | AX15: =IF(AY15="","",TEXT($AY15,"d")) | AZ15: =IF(BA15="","",IF(各種設定金額!$B$7="","○○県",各種設定金額!$B$7)) | BC15: =IF(TRIM(BE15)="","",BD15&BE15&BF15) | BF15: 号 | BG15: =IF(BM15="","",TEXT($BM15,"ggg")) | BH15: =IF(BM15="","",TEXT($BM15,"gg")) | BI15: =IF(BM15="","",TEXT($BM15,"g")) | BJ15: =IF(BM15="","",TEXT($BM15,"e")) | BK15: =IF(BM15="","",TEXT($BM15,"m")) | BL15: =IF(BM15="","",TEXT($BM15,"d")) | BN15: =IF(BO15="","",IF(各種設定金額!$B$7="","○○県",各種設定金額!$B$7)) | BQ15: =IF(TRIM(BS15)="","",BR15&BS15&BT15) | BT15: 号 | BU15: =IF(CA15="","",TEXT($CA15,"ggg")) | BV15: =IF(CA15="","",TEXT($CA15,"gg")) | BW15: =IF(CA15="","",TEXT($CA15,"g")) | BX15: =IF(CA15="","",TEXT($CA15,"e")) | BY15: =IF(CA15="","",TEXT($CA15,"m")) | BZ15: =IF(CA15="","",TEXT($CA15,"d")) | CB15: =IF(COUNT(AY15,BM15,CA15)=0,"",TEXT(DATE(YEAR(MIN(AY15,BM15,CA15))+3,9,14),"g")) | CC15: =IF(COUNT(AY15,BM15,CA15)=0,"",VALUE(TEXT(DATE(YEAR(MIN(AY15,BM15,CA15))+3,9,14),"e"))) | CH15: =YEAR(TODAY()) -> 2026 | CI15: =TEXT($CO15,"ggg") -> 令和 | CJ15: =TEXT($CO15,"g") -> R | CK15: =TEXT($CO15,"e") -> 8 | CL15: =MONTH(TODAY()) -> 10 | CM15: =DAY(TODAY()) -> 24 | CO15: =TODAY() -> 46319
A16: =IF(B16="","",ROW()-ROW(会員表[#Headers])) | C16: {=_xlfn.LET(_xlpm.s,PHONETIC(B16),_xlpm.c,_xlfn.UNICODE(MID(_xlpm.s,_xlfn.SEQUENCE(LEN(_xlpm.s)),1)),IF(_xlpm.s="","",_xlfn.CONCAT(_xlfn.UNICHAR(_xlpm.c-96*(_xlpm.c>=12449)*(_xlpm.c<=12534)))))} | D16: {=_xlfn.LET(_xlpm.s,PHONETIC(B16),_xlpm.c,_xlfn.UNICODE(MID(_xlpm.s,_xlfn.SEQUENCE(LEN(_xlpm.s)),1)),IF(_xlpm.s="","",_xlfn.CONCAT(_xlfn.UNICHAR(_xlpm.c+96*(_xlpm.c>=12353)*(_xlpm.c<=12438)))))} | E16: =IF(N16="","",DATEDIF(N16,TODAY(),"Y")) | F16: =IF(I16="昭","〇","") | G16: =IF(I16="平","〇","") | H16: =IF(I16="令","〇","") | I16: =IF($N16="","",TEXT($N16,"gg")) | J16: =IF($N16="","",TEXT($N16,"ggg")) | K16: =IF($N16="","",TEXT($N16,"e")) | L16: =IF($N16="","",TEXT($N16,"m")) | M16: =IF($N16="","",TEXT($N16,"d")) | P16: =IFERROR(LEFT(O16,FIND("-",O16)-1),"") | Q16: =IFERROR(RIGHT(O16,LEN(O16)-FIND("-",O16)),"") | R16: =IFERROR(LEFT(Q16,FIND("-",Q16)-1),"") | S16: =IFERROR(RIGHT(Q16,LEN(Q16)-FIND("-",Q16)),"") | U16: =IFERROR(LEFT(T16,FIND("-",T16)-1),"") | V16: =IFERROR(RIGHT(T16,LEN(T16)-FIND("-",T16)),"") | W16: =IFERROR(LEFT(V16,FIND("-",V16)-1),"") | X16: =IFERROR(RIGHT(V16,LEN(V16)-FIND("-",V16)),"") | Z16: =IF(Y16="","",LEFT(SUBSTITUTE(ASC(Y16),"-",""),3)) | AA16: - | AB16: =IF(Y16="","",MID(SUBSTITUTE(ASC(Y16),"-",""),4,4)) | AE16: =IF(AK16="","",TEXT($AK16,"ggg")) | AF16: =IF(AK16="","",TEXT($AK16,"gg")) | AG16: =IF(AK16="","",TEXT($AK16,"g")) | AH16: =IF(AK16="","",TEXT($AK16,"e")) | AI16: =IF(AK16="","",TEXT($AK16,"m")) | AJ16: =IF(AK16="","",TEXT($AK16,"d")) | AL16: =IF(AM16="","",IF(各種設定金額!$B$7="","○○県",各種設定金額!$B$7)) | AO16: =IF(TRIM(AQ16)="","",AP16&AQ16&AR16) | AR16: 号 | AS16: =IF(AY16="","",TEXT($AY16,"ggg")) | AT16: =IF(AY16="","",TEXT($AY16,"gg")) | AU16: =IF(AY16="","",TEXT($AY16,"g")) | AV16: =IF(AY16="","",TEXT($AY16,"e")) | AW16: =IF(AY16="","",TEXT($AY16,"m")) | AX16: =IF(AY16="","",TEXT($AY16,"d")) | AZ16: =IF(BA16="","",IF(各種設定金額!$B$7="","○○県",各種設定金額!$B$7)) | BC16: =IF(TRIM(BE16)="","",BD16&BE16&BF16) | BF16: 号 | BG16: =IF(BM16="","",TEXT($BM16,"ggg")) | BH16: =IF(BM16="","",TEXT($BM16,"gg")) | BI16: =IF(BM16="","",TEXT($BM16,"g")) | BJ16: =IF(BM16="","",TEXT($BM16,"e")) | BK16: =IF(BM16="","",TEXT($BM16,"m")) | BL16: =IF(BM16="","",TEXT($BM16,"d")) | BN16: =IF(BO16="","",IF(各種設定金額!$B$7="","○○県",各種設定金額!$B$7)) | BQ16: =IF(TRIM(BS16)="","",BR16&BS16&BT16) | BT16: 号 | BU16: =IF(CA16="","",TEXT($CA16,"ggg")) | BV16: =IF(CA16="","",TEXT($CA16,"gg")) | BW16: =IF(CA16="","",TEXT($CA16,"g")) | BX16: =IF(CA16="","",TEXT($CA16,"e")) | BY16: =IF(CA16="","",TEXT($CA16,"m")) | BZ16: =IF(CA16="","",TEXT($CA16,"d")) | CB16: =IF(COUNT(AY16,BM16,CA16)=0,"",TEXT(DATE(YEAR(MIN(AY16,BM16,CA16))+3,9,14),"g")) | CC16: =IF(COUNT(AY16,BM16,CA16)=0,"",VALUE(TEXT(DATE(YEAR(MIN(AY16,BM16,CA16))+3,9,14),"e"))) | CH16: =YEAR(TODAY()) -> 2026 | CI16: =TEXT($CO16,"ggg") -> 令和 | CJ16: =TEXT($CO16,"g") -> R | CK16: =TEXT($CO16,"e") -> 8 | CL16: =MONTH(TODAY()) -> 10 | CM16: =DAY(TODAY()) -> 24 | CO16: =TODAY() -> 46319
A17: =IF(B17="","",ROW()-ROW(会員表[#Headers])) | C17: {=_xlfn.LET(_xlpm.s,PHONETIC(B17),_xlpm.c,_xlfn.UNICODE(MID(_xlpm.s,_xlfn.SEQUENCE(LEN(_xlpm.s)),1)),IF(_xlpm.s="","",_xlfn.CONCAT(_xlfn.UNICHAR(_xlpm.c-96*(_xlpm.c>=12449)*(_xlpm.c<=12534)))))} | D17: {=_xlfn.LET(_xlpm.s,PHONETIC(B17),_xlpm.c,_xlfn.UNICODE(MID(_xlpm.s,_xlfn.SEQUENCE(LEN(_xlpm.s)),1)),IF(_xlpm.s="","",_xlfn.CONCAT(_xlfn.UNICHAR(_xlpm.c+96*(_xlpm.c>=12353)*(_xlpm.c<=12438)))))} | E17: =IF(N17="","",DATEDIF(N17,TODAY(),"Y")) | F17: =IF(I17="昭","〇","") | G17: =IF(I17="平","〇","") | H17: =IF(I17="令","〇","") | I17: =IF($N17="","",TEXT($N17,"gg")) | J17: =IF($N17="","",TEXT($N17,"ggg")) | K17: =IF($N17="","",TEXT($N17,"e")) | L17: =IF($N17="","",TEXT($N17,"m")) | M17: =IF($N17="","",TEXT($N17,"d")) | P17: =IFERROR(LEFT(O17,FIND("-",O17)-1),"") | Q17: =IFERROR(RIGHT(O17,LEN(O17)-FIND("-",O17)),"") | R17: =IFERROR(LEFT(Q17,FIND("-",Q17)-1),"") | S17: =IFERROR(RIGHT(Q17,LEN(Q17)-FIND("-",Q17)),"") | U17: =IFERROR(LEFT(T17,FIND("-",T17)-1),"") | V17: =IFERROR(RIGHT(T17,LEN(T17)-FIND("-",T17)),"") | W17: =IFERROR(LEFT(V17,FIND("-",V17)-1),"") | X17: =IFERROR(RIGHT(V17,LEN(V17)-FIND("-",V17)),"") | Z17: =IF(Y17="","",LEFT(SUBSTITUTE(ASC(Y17),"-",""),3)) | AA17: - | AB17: =IF(Y17="","",MID(SUBSTITUTE(ASC(Y17),"-",""),4,4)) | AE17: =IF(AK17="","",TEXT($AK17,"ggg")) | AF17: =IF(AK17="","",TEXT($AK17,"gg")) | AG17: =IF(AK17="","",TEXT($AK17,"g")) | AH17: =IF(AK17="","",TEXT($AK17,"e")) | AI17: =IF(AK17="","",TEXT($AK17,"m")) | AJ17: =IF(AK17="","",TEXT($AK17,"d")) | AL17: =IF(AM17="","",IF(各種設定金額!$B$7="","○○県",各種設定金額!$B$7)) | AO17: =IF(TRIM(AQ17)="","",AP17&AQ17&AR17) | AR17: 号 | AS17: =IF(AY17="","",TEXT($AY17,"ggg")) | AT17: =IF(AY17="","",TEXT($AY17,"gg")) | AU17: =IF(AY17="","",TEXT($AY17,"g")) | AV17: =IF(AY17="","",TEXT($AY17,"e")) | AW17: =IF(AY17="","",TEXT($AY17,"m")) | AX17: =IF(AY17="","",TEXT($AY17,"d")) | AZ17: =IF(BA17="","",IF(各種設定金額!$B$7="","○○県",各種設定金額!$B$7)) | BC17: =IF(TRIM(BE17)="","",BD17&BE17&BF17) | BF17: 号 | BG17: =IF(BM17="","",TEXT($BM17,"ggg")) | BH17: =IF(BM17="","",TEXT($BM17,"gg")) | BI17: =IF(BM17="","",TEXT($BM17,"g")) | BJ17: =IF(BM17="","",TEXT($BM17,"e")) | BK17: =IF(BM17="","",TEXT($BM17,"m")) | BL17: =IF(BM17="","",TEXT($BM17,"d")) | BN17: =IF(BO17="","",IF(各種設定金額!$B$7="","○○県",各種設定金額!$B$7)) | BQ17: =IF(TRIM(BS17)="","",BR17&BS17&BT17) | BT17: 号 | BU17: =IF(CA17="","",TEXT($CA17,"ggg")) | BV17: =IF(CA17="","",TEXT($CA17,"gg")) | BW17: =IF(CA17="","",TEXT($CA17,"g")) | BX17: =IF(CA17="","",TEXT($CA17,"e")) | BY17: =IF(CA17="","",TEXT($CA17,"m")) | BZ17: =IF(CA17="","",TEXT($CA17,"d")) | CB17: =IF(COUNT(AY17,BM17,CA17)=0,"",TEXT(DATE(YEAR(MIN(AY17,BM17,CA17))+3,9,14),"g")) | CC17: =IF(COUNT(AY17,BM17,CA17)=0,"",VALUE(TEXT(DATE(YEAR(MIN(AY17,BM17,CA17))+3,9,14),"e"))) | CH17: =YEAR(TODAY()) -> 2026 | CI17: =TEXT($CO17,"ggg") -> 令和 | CJ17: =TEXT($CO17,"g") -> R | CK17: =TEXT($CO17,"e") -> 8 | CL17: =MONTH(TODAY()) -> 10 | CM17: =DAY(TODAY()) -> 24 | CO17: =TODAY() -> 46319
A18: =IF(B18="","",ROW()-ROW(会員表[#Headers])) | C18: {=_xlfn.LET(_xlpm.s,PHONETIC(B18),_xlpm.c,_xlfn.UNICODE(MID(_xlpm.s,_xlfn.SEQUENCE(LEN(_xlpm.s)),1)),IF(_xlpm.s="","",_xlfn.CONCAT(_xlfn.UNICHAR(_xlpm.c-96*(_xlpm.c>=12449)*(_xlpm.c<=12534)))))} | D18: {=_xlfn.LET(_xlpm.s,PHONETIC(B18),_xlpm.c,_xlfn.UNICODE(MID(_xlpm.s,_xlfn.SEQUENCE(LEN(_xlpm.s)),1)),IF(_xlpm.s="","",_xlfn.CONCAT(_xlfn.UNICHAR(_xlpm.c+96*(_xlpm.c>=12353)*(_xlpm.c<=12438)))))} | E18: =IF(N18="","",DATEDIF(N18,TODAY(),"Y")) | F18: =IF(I18="昭","〇","") | G18: =IF(I18="平","〇","") | H18: =IF(I18="令","〇","") | I18: =IF($N18="","",TEXT($N18,"gg")) | J18: =IF($N18="","",TEXT($N18,"ggg")) | K18: =IF($N18="","",TEXT($N18,"e")) | L18: =IF($N18="","",TEXT($N18,"m")) | M18: =IF($N18="","",TEXT($N18,"d")) | P18: =IFERROR(LEFT(O18,FIND("-",O18)-1),"") | Q18: =IFERROR(RIGHT(O18,LEN(O18)-FIND("-",O18)),"") | R18: =IFERROR(LEFT(Q18,FIND("-",Q18)-1),"") | S18: =IFERROR(RIGHT(Q18,LEN(Q18)-FIND("-",Q18)),"") | U18: =IFERROR(LEFT(T18,FIND("-",T18)-1),"") | V18: =IFERROR(RIGHT(T18,LEN(T18)-FIND("-",T18)),"") | W18: =IFERROR(LEFT(V18,FIND("-",V18)-1),"") | X18: =IFERROR(RIGHT(V18,LEN(V18)-FIND("-",V18)),"") | Z18: =IF(Y18="","",LEFT(SUBSTITUTE(ASC(Y18),"-",""),3)) | AA18: - | AB18: =IF(Y18="","",MID(SUBSTITUTE(ASC(Y18),"-",""),4,4)) | AE18: =IF(AK18="","",TEXT($AK18,"ggg")) | AF18: =IF(AK18="","",TEXT($AK18,"gg")) | AG18: =IF(AK18="","",TEXT($AK18,"g")) | AH18: =IF(AK18="","",TEXT($AK18,"e")) | AI18: =IF(AK18="","",TEXT($AK18,"m")) | AJ18: =IF(AK18="","",TEXT($AK18,"d")) | AL18: =IF(AM18="","",IF(各種設定金額!$B$7="","○○県",各種設定金額!$B$7)) | AO18: =IF(TRIM(AQ18)="","",AP18&AQ18&AR18) | AR18: 号 | AS18: =IF(AY18="","",TEXT($AY18,"ggg")) | AT18: =IF(AY18="","",TEXT($AY18,"gg")) | AU18: =IF(AY18="","",TEXT($AY18,"g")) | AV18: =IF(AY18="","",TEXT($AY18,"e")) | AW18: =IF(AY18="","",TEXT($AY18,"m")) | AX18: =IF(AY18="","",TEXT($AY18,"d")) | AZ18: =IF(BA18="","",IF(各種設定金額!$B$7="","○○県",各種設定金額!$B$7)) | BC18: =IF(TRIM(BE18)="","",BD18&BE18&BF18) | BF18: 号 | BG18: =IF(BM18="","",TEXT($BM18,"ggg")) | BH18: =IF(BM18="","",TEXT($BM18,"gg")) | BI18: =IF(BM18="","",TEXT($BM18,"g")) | BJ18: =IF(BM18="","",TEXT($BM18,"e")) | BK18: =IF(BM18="","",TEXT($BM18,"m")) | BL18: =IF(BM18="","",TEXT($BM18,"d")) | BN18: =IF(BO18="","",IF(各種設定金額!$B$7="","○○県",各種設定金額!$B$7)) | BQ18: =IF(TRIM(BS18)="","",BR18&BS18&BT18) | BT18: 号 | BU18: =IF(CA18="","",TEXT($CA18,"ggg")) | BV18: =IF(CA18="","",TEXT($CA18,"gg")) | BW18: =IF(CA18="","",TEXT($CA18,"g")) | BX18: =IF(CA18="","",TEXT($CA18,"e")) | BY18: =IF(CA18="","",TEXT($CA18,"m")) | BZ18: =IF(CA18="","",TEXT($CA18,"d")) | CB18: =IF(COUNT(AY18,BM18,CA18)=0,"",TEXT(DATE(YEAR(MIN(AY18,BM18,CA18))+3,9,14),"g")) | CC18: =IF(COUNT(AY18,BM18,CA18)=0,"",VALUE(TEXT(DATE(YEAR(MIN(AY18,BM18,CA18))+3,9,14),"e"))) | CH18: =YEAR(TODAY()) -> 2026 | CI18: =TEXT($CO18,"ggg") -> 令和 | CJ18: =TEXT($CO18,"g") -> R | CK18: =TEXT($CO18,"e") -> 8 | CL18: =MONTH(TODAY()) -> 10 | CM18: =DAY(TODAY()) -> 24 | CO18: =TODAY() -> 46319
... A151: =IF(B151="","",ROW()-ROW(会員表[#Headers])) | C151: {=_xlfn.LET(_xlpm.s,PHONETIC(B151),_xlpm.c,_xlfn.UNICODE(MID(_xlpm.s,_xlfn.SEQUENCE(LEN(_xlpm.s)),1)),IF(_xlpm.s="","",_xlfn.CONCAT(_xlfn.UNICHAR(_xlpm.c-96*(_xlpm.c>=12449)*(_xlpm.c<=12534)))))} | D151: {=_xlfn.LET(_xlpm.s,PHONETIC(B151),_xlpm.c,_xlfn.UNICODE(MID(_xlpm.s,_xlfn.SEQUENCE(LEN(_xlpm.s)),1)),IF(_xlpm.s="","",_xlfn.CONCAT(_xlfn.UNICHAR(_xlpm.c+96*(_xlpm.c>=12353)*(_xlpm.c<=12438)))))} | E151: =IF(N151="","",DATEDIF(N151,TODAY(),"Y")) | F151: =IF(I151="昭","〇","") | G151: =IF(I151="平","〇","") | H151: =IF(I151="令","〇","") | I151: =IF($N151="","",TEXT($N151,"gg")) | J151: =IF($N151="","",TEXT($N151,"ggg")) | K151: =IF($N151="","",TEXT($N151,"e")) | L151: =IF($N151="","",TEXT($N151,"m")) | M151: =IF($N151="","",TEXT($N151,"d")) | P151: =IFERROR(LEFT(O151,FIND("-",O151)-1),"") | Q151: =IFERROR(RIGHT(O151,LEN(O151)-FIND("-",O151)),"") | R151: =IFERROR(LEFT(Q151,FIND("-",Q151)-1),"") | S151: =IFERROR(RIGHT(Q151,LEN(Q151)-FIND("-",Q151)),"") | U151: =IFERROR(LEFT(T151,FIND("-",T151)-1),"") | V151: =IFERROR(RIGHT(T151,LEN(T151)-FIND("-",T151)),"") | W151: =IFERROR(LEFT(V151,FIND("-",V151)-1),"") | X151: =IFERROR(RIGHT(V151,LEN(V151)-FIND("-",V151)),"") | Z151: =IF(Y151="","",LEFT(SUBSTITUTE(ASC(Y151),"-",""),3)) | AA151: - | AB151: =IF(Y151="","",MID(SUBSTITUTE(ASC(Y151),"-",""),4,4)) | AE151: =IF(AK151="","",TEXT($AK151,"ggg")) | AF151: =IF(AK151="","",TEXT($AK151,"gg")) | AG151: =IF(AK151="","",TEXT($AK151,"g")) | AH151: =IF(AK151="","",TEXT($AK151,"e")) | AI151: =IF(AK151="","",TEXT($AK151,"m")) | AJ151: =IF(AK151="","",TEXT($AK151,"d")) | AL151: =IF(AM151="","",IF(各種設定金額!$B$7="","○○県",各種設定金額!$B$7)) | AO151: =IF(TRIM(AQ151)="","",AP151&AQ151&AR151) | AR151: 号 | AS151: =IF(AY151="","",TEXT($AY151,"ggg")) | AT151: =IF(AY151="","",TEXT($AY151,"gg")) | AU151: =IF(AY151="","",TEXT($AY151,"g")) | AV151: =IF(AY151="","",TEXT($AY151,"e")) | AW151: =IF(AY151="","",TEXT($AY151,"m")) | AX151: =IF(AY151="","",TEXT($AY151,"d")) | AZ151: =IF(BA151="","",IF(各種設定金額!$B$7="","○○県",各種設定金額!$B$7)) | BC151: =IF(TRIM(BE151)="","",BD151&BE151&BF151) | BF151: 号 | BG151: =IF(BM151="","",TEXT($BM151,"ggg")) | BH151: =IF(BM151="","",TEXT($BM151,"gg")) | BI151: =IF(BM151="","",TEXT($BM151,"g")) | BJ151: =IF(BM151="","",TEXT($BM151,"e")) | BK151: =IF(BM151="","",TEXT($BM151,"m")) | BL151: =IF(BM151="","",TEXT($BM151,"d")) | BN151: =IF(BO151="","",IF(各種設定金額!$B$7="","○○県",各種設定金額!$B$7)) | BQ151: =IF(TRIM(BS151)="","",BR151&BS151&BT151) | BT151: 号 | BU151: =IF(CA151="","",TEXT($CA151,"ggg")) | BV151: =IF(CA151="","",TEXT($CA151,"gg")) | BW151: =IF(CA151="","",TEXT($CA151,"g")) | BX151: =IF(CA151="","",TEXT($CA151,"e")) | BY151: =IF(CA151="","",TEXT($CA151,"m")) | BZ151: =IF(CA151="","",TEXT($CA151,"d")) | CB151: =IF(COUNT(AY151,BM151,CA151)=0,"",TEXT(DATE(YEAR(MIN(AY151,BM151,CA151))+3,9,14),"g")) | CC151: =IF(COUNT(AY151,BM151,CA151)=0,"",VALUE(TEXT(DATE(YEAR(MIN(AY151,BM151,CA151))+3,9,14),"e"))) | CH151: =YEAR(TODAY()) -> 2026 | CI151: =TEXT($CO151,"ggg") -> 令和 | CJ151: =TEXT($CO151,"g") -> R | CK151: =TEXT($CO151,"e") -> 8 | CL151: =MONTH(TODAY()) -> 10 | CM151: =DAY(TODAY()) -> 24 | CO151: =TODAY() -> 46319

Sheet 会員名簿
A1: ○○支部 会員名簿 令和 年 月
G2: 銃 | I2: わな | K2: 網 | M2: 免 | N2: 許
A3: No | B3: 氏 名 | C3: 携 帯 電 話 | D3: 固 定 電 話 | E3: 郵便番号 | F3: 住 所 | G3: 免 | H3: 登 | I3: 免 | J3: 登 | K3: 免 | L3: 登 | M3: 次 | N3: 回
G4: 許 | H4: 録 | I4: 許 | J4: 録 | K4: 許 | L4: 録 | M4: 更 | N4: 新
A5: =IF(B5="","",IF(SUBTOTAL(103,B5)=0,"",SUBTOTAL(103,$B$5:B5))) -> 1 | B5: =INDEX(Sheet1!$B:$B,ROWS($A$5:$A5)+1)&"" -> 見本 太郎 | C5: =INDEX(Sheet1!$O:$O,ROWS($A$5:$A5)+1)&"" -> 090-0000-0001 | D5: =INDEX(Sheet1!$T:$T,ROWS($A$5:$A5)+1)&"" -> 000-000-0001 | E5: =INDEX(Sheet1!$Y:$Y,ROWS($A$5:$A5)+1)&"" -> 000-0001 | F5: =INDEX(Sheet1!$AC:$AC,ROWS($A$5:$A5)+1)&"" -> 見本市見本町1丁目2-3 | G5: =INDEX(Sheet1!$AM:$AM,ROWS($A$5:$A5)+1)&"" -> ✔ | H5: =INDEX(Sheet1!$AN:$AN,ROWS($A$5:$A5)+1)&"" -> ✔ | I5: =INDEX(Sheet1!$BA:$BA,ROWS($A$5:$A5)+1)&"" -> ✔ | J5: =INDEX(Sheet1!$BB:$BB,ROWS($A$5:$A5)+1)&"" -> ✔ | K5: =INDEX(Sheet1!$BO:$BO,ROWS($A$5:$A5)+1)&"" | L5: =INDEX(Sheet1!$BP:$BP,ROWS($A$5:$A5)+1)&"" | M5: =INDEX(Sheet1!$CB:$CB,ROWS($A$5:$A5)+1)&"" -> R | N5: =IF(INDEX(Sheet1!$CC:$CC,ROWS($A$5:$A5)+1)="","",INDEX(Sheet1!$CC:$CC,ROWS($A$5:$A5)+1)) -> 9
A6: =IF(B6="","",IF(SUBTOTAL(103,B6)=0,"",SUBTOTAL(103,$B$5:B6))) -> 2 | B6: =INDEX(Sheet1!$B:$B,ROWS($A$5:$A6)+1)&"" -> 例示 花子 | C6: =INDEX(Sheet1!$O:$O,ROWS($A$5:$A6)+1)&"" -> 080-0000-0002 | D6: =INDEX(Sheet1!$T:$T,ROWS($A$5:$A6)+1)&"" | E6: =INDEX(Sheet1!$Y:$Y,ROWS($A$5:$A6)+1)&"" -> 000-0002 | F6: =INDEX(Sheet1!$AC:$AC,ROWS($A$5:$A6)+1)&"" -> 例示市例示町2丁目3-4 | G6: =INDEX(Sheet1!$AM:$AM,ROWS($A$5:$A6)+1)&"" | H6: =INDEX(Sheet1!$AN:$AN,ROWS($A$5:$A6)+1)&"" | I6: =INDEX(Sheet1!$BA:$BA,ROWS($A$5:$A6)+1)&"" -> ✔ | J6: =INDEX(Sheet1!$BB:$BB,ROWS($A$5:$A6)+1)&"" -> ✔ | K6: =INDEX(Sheet1!$BO:$BO,ROWS($A$5:$A6)+1)&"" | L6: =INDEX(Sheet1!$BP:$BP,ROWS($A$5:$A6)+1)&"" | M6: =INDEX(Sheet1!$CB:$CB,ROWS($A$5:$A6)+1)&"" -> R | N6: =IF(INDEX(Sheet1!$CC:$CC,ROWS($A$5:$A6)+1)="","",INDEX(Sheet1!$CC:$CC,ROWS($A$5:$A6)+1)) -> 8
A7: =IF(B7="","",IF(SUBTOTAL(103,B7)=0,"",SUBTOTAL(103,$B$5:B7))) -> 3 | B7: =INDEX(Sheet1!$B:$B,ROWS($A$5:$A7)+1)&"" -> 記入 次郎 | C7: =INDEX(Sheet1!$O:$O,ROWS($A$5:$A7)+1)&"" -> 070-0000-0003 | D7: =INDEX(Sheet1!$T:$T,ROWS($A$5:$A7)+1)&"" | E7: =INDEX(Sheet1!$Y:$Y,ROWS($A$5:$A7)+1)&"" -> 000-0003 | F7: =INDEX(Sheet1!$AC:$AC,ROWS($A$5:$A7)+1)&"" -> 記入市記入町3丁目4-5 | G7: =INDEX(Sheet1!$AM:$AM,ROWS($A$5:$A7)+1)&"" -> ✔ | H7: =INDEX(Sheet1!$AN:$AN,ROWS($A$5:$A7)+1)&"" -> 2️⃣ | I7: =INDEX(Sheet1!$BA:$BA,ROWS($A$5:$A7)+1)&"" | J7: =INDEX(Sheet1!$BB:$BB,ROWS($A$5:$A7)+1)&"" | K7: =INDEX(Sheet1!$BO:$BO,ROWS($A$5:$A7)+1)&"" -> ✔ | L7: =INDEX(Sheet1!$BP:$BP,ROWS($A$5:$A7)+1)&"" -> ✔ | M7: =INDEX(Sheet1!$CB:$CB,ROWS($A$5:$A7)+1)&"" -> R | N7: =IF(INDEX(Sheet1!$CC:$CC,ROWS($A$5:$A7)+1)="","",INDEX(Sheet1!$CC:$CC,ROWS($A$5:$A7)+1)) -> 10
A8: =IF(B8="","",IF(SUBTOTAL(103,B8)=0,"",SUBTOTAL(103,$B$5:B8))) -> 4 | B8: =INDEX(Sheet1!$B:$B,ROWS($A$5:$A8)+1)&"" -> 試験 三郎 | C8: =INDEX(Sheet1!$O:$O,ROWS($A$5:$A8)+1)&"" -> 090-0000-0004 | D8: =INDEX(Sheet1!$T:$T,ROWS($A$5:$A8)+1)&"" -> 000-000-0004 | E8: =INDEX(Sheet1!$Y:$Y,ROWS($A$5:$A8)+1)&"" -> 000-0004 | F8: =INDEX(Sheet1!$AC:$AC,ROWS($A$5:$A8)+1)&"" -> 試験市試験町4丁目5-6 | G8: =INDEX(Sheet1!$AM:$AM,ROWS($A$5:$A8)+1)&"" -> ✔ | H8: =INDEX(Sheet1!$AN:$AN,ROWS($A$5:$A8)+1)&"" -> ✔ | I8: =INDEX(Sheet1!$BA:$BA,ROWS($A$5:$A8)+1)&"" | J8: =INDEX(Sheet1!$BB:$BB,ROWS($A$5:$A8)+1)&"" | K8: =INDEX(Sheet1!$BO:$BO,ROWS($A$5:$A8)+1)&"" | L8: =INDEX(Sheet1!$BP:$BP,ROWS($A$5:$A8)+1)&"" | M8: =INDEX(Sheet1!$CB:$CB,ROWS($A$5:$A8)+1)&"" -> R | N8: =IF(INDEX(Sheet1!$CC:$CC,ROWS($A$5:$A8)+1)="","",INDEX(Sheet1!$CC:$CC,ROWS($A$5:$A8)+1)) -> 8
